Workbook

Sheet TABELA CARBONATACAO
G9: ES-01 | H9: túnel de descarga-PT05
C10: Column1 | G10: ES-02 | H10: túnel de descarga-PT03
C11: ES-01 (túnel de descarga-PT05) | G11: ES-03 | H11: túnel de descarga-PT06
C12: ES-02 (túnel de descarga-PT03) | G12: ES-04 | H12: estaca 71-N
C13: ES-03 (túnel de descarga-PT06) | G13: ES-05 | H13: estaca 71-O
C14: ES-04 (estaca 71-N) | G14: ES-06 | H14: estaca 71-S
C15: ES-05 (estaca 71-O) | G15: ES-07 | H15: estaca 71-L
C16: ES-06 (estaca 71-S) | G16: ES-08 | H16: estaca 60-N
C17: ES-07 (estaca 71-L) | G17: ES-09 | H17: estaca 60-O
C18: ES-08 (estaca 60-N) | G18: ES-10 | H18: estaca 60-S
C19: ES-09 (estaca 60-O) | G19: ES-11 | H19: estaca 60-L
C20: ES-10 (estaca 60-S) | G20: ES-12 | H20: estaca 44-N | J20: 1 | K20: EC-13 (Túnel de descarga-PT05) | L20: 5.2 | M20: 4.5 | N20: 4.9 | O20: 5 | P20: =AVERAGE(L20:O20) -> 4.9 | Q20: =P20*10 -> 49
C21: ES-11 (estaca 60-L) | G21: ES-13 | H21: estaca 44-O | J21: 2 | K21: EC-14 (túnel de descarga-PT03) | L21: 5.5 | M21: 5.8 | N21: 6.1 | O21: 6.3 | P21: =AVERAGE(L21:O21) -> 5.925 | Q21: =P21*10 -> 59.25
C22: ES-12 (estaca 44-N) | G22: ES-14 | H22: estaca 44-S | J22: 3 | K22: EC-15 (túnel de descarga-PT06) | L22: 6.5 | M22: 5.5 | N22: 6.7 | O22: 7 | P22: =AVERAGE(L22:O22) -> 6.425 | Q22: =P22*10 -> 64.25
C23: ES-13 (estaca 44-O) | G23: ES-15 | H23: estaca 44-L | J23: 4 | K23: EC-01 (estaca 71-N) | L23: 5 | M23: 4.8 | N23: 5 | O23: 5 | P23: =AVERAGE(L23:O23) -> 4.95 | Q23: =P23*10 -> 49.5
C24: ES-14 (estaca 44-S) | G24: ES-16 | H24: estaca 24-N | J24: 5 | K24: EC-02 (estaca 71-O) | L24: 5 | M24: 4.7 | N24: 5.3 | O24: 5.2 | P24: =AVERAGE(L24:O24) -> 5.05 | Q24: =P24*10 -> 50.5
C25: ES-15 (estaca 44-L) | G25: ES-17 | H25: estaca 24-S | J25: 6 | K25: EC-03 (estaca 71-S) | L25: 5 | M25: 5.8 | N25: 5.5 | O25: 5.7 | P25: =AVERAGE(L25:O25) -> 5.5 | Q25: =P25*10 -> 55
C26: ES-16 (estaca 24-N) | G26: ES-18 | H26: estaca 24-L | J26: 7 | K26: EC-04 (estaca 71-L) | L26: 6 | M26: 5.6 | N26: 5.4 | O26: 5.8 | P26: =AVERAGE(L26:O26) -> 5.7 | Q26: =P26*10 -> 57
C27: ES-17 (estaca 24-S) | G27: ES-19 | H27: capitel estaca 71-N | J27: 8 | K27: EC-05 (estaca 60-N) | L27: 6.8 | M27: 7 | N27: 7.2 | O27: 7 | P27: =AVERAGE(L27:O27) -> 7 | Q27: =P27*10 -> 70
C28: ES-18 (estaca 24-L) | G28: ES-20 | H28: capitel estaca 71-S | J28: 9 | K28: EC-06 (estaca 60-O) | L28: 5.5 | M28: 6 | N28: 6.5 | O28: 6.8 | P28: =AVERAGE(L28:O28) -> 6.2 | Q28: =P28*10 -> 62
C29: ES-19 (capitel estaca 71-N) | G29: ES-21 | H29: capitel estaca 60-N | J29: 12 | K29: EC-07 (estaca 44-N) | L29: 6.4 | M29: 6.3 | N29: 6.7 | O29: 6.5 | P29: =AVERAGE(L29:O29) -> 6.475 | Q29: =P29*10 -> 64.75
C30: ES-20 (capitel estaca 71-S) | G30: ES-22 | H30: fundo da laje-PLE 02 | J30: 16 | K30: EC-08 (estaca 24-N) | L30: 7 | M30: 6.5 | N30: 6.2 | O30: 6.6 | P30: =AVERAGE(L30:O30) -> 6.575 | Q30: =P30*10 -> 65.75
C31: ES-21 (capitel estaca 60-N) | G31: ES-23 | H31: bloco de fundação-CP08 | J31: 19 | K31: EC-11 (capitel estaca 71-N) | L31: 5.2 | M31: 5.3 | N31: 5 | O31: 5 | P31: =AVERAGE(L31:O31) -> 5.125 | Q31: =P31*10 -> 51.25
C32: ES-22 (fundo da laje-PLE 02) | G32: ES-24 | H32: fundo da laje-PLE 04 | J32: 21 | K32: EC-09 (capitel estaca 60-N) | L32: 4 | M32: 4.2 | N32: 4.7 | O32: 4.2 | P32: =AVERAGE(L32:O32) -> 4.275 | Q32: =P32*10 -> 42.75
G33: ES-25 | H33: fundo da laje-PLE 03 | J33: 22 | K33: EC-10 (capitel estaca 60-L) | L33: 4.5 | M33: 4.3 | N33: 4.4 | O33: 4.4 | P33: =AVERAGE(L33:O33) -> 4.4 | Q33: =P33*10 -> 44
G34: ES-26 | H34: fundo da laje-PLE 01
G35: ES-27 | H35: bloco de fundação-CP09 | K35: Column1 | L35: 5 | M35: 4.8 | N35: 5 | O35: 5 | P35: =AVERAGE(L35:O35) -> 4.95 | Q35: =P35*10 -> 49.5
K36: EC-01 (estaca 71-N) | L36: 5 | M36: 4.7 | N36: 5.3 | O36: 5.2 | P36: =AVERAGE(L36:O36) -> 5.05 | Q36: =P36*10 -> 50.5
K37: EC-02 (estaca 71-O) | L37: 5 | M37: 5.8 | N37: 5.5 | O37: 5.7 | P37: =AVERAGE(L37:O37) -> 5.5 | Q37: =P37*10 -> 55
K38: EC-03 (estaca 71-S) | L38: 6 | M38: 5.6 | N38: 5.4 | O38: 5.8 | P38: =AVERAGE(L38:O38) -> 5.7 | Q38: =P38*10 -> 57
K39: EC-04 (estaca 71-L) | L39: 6.8 | M39: 7 | N39: 7.2 | O39: 7 | P39: =AVERAGE(L39:O39) -> 7 | Q39: =P39*10 -> 70
K40: EC-05 (estaca 60-N) | L40: 5.5 | M40: 6 | N40: 6.5 | O40: 6.8 | P40: =AVERAGE(L40:O40) -> 6.2 | Q40: =P40*10 -> 62
K41: EC-06 (estaca 60-O) | L41: 6.4 | M41: 6.3 | N41: 6.7 | O41: 6.5 | P41: =AVERAGE(L41:O41) -> 6.475 | Q41: =P41*10 -> 64.75
K42: EC-07 (estaca 44-N) | L42: 7 | M42: 6.5 | N42: 6.2 | O42: 6.6 | P42: =AVERAGE(L42:O42) -> 6.575 | Q42: =P42*10 -> 65.75
K43: EC-08 (estaca 24-N) | L43: 4 | M43: 4.2 | N43: 4.7 | O43: 4.2 | P43: =AVERAGE(L43:O43) -> 4.275 | Q43: =P43*10 -> 42.75
K44: EC-09 (capitel estaca 60-N) | L44: 4.5 | M44: 4.3 | N44: 4.4 | O44: 4.4 | P44: =AVERAGE(L44:O44) -> 4.4 | Q44: =P44*10 -> 44
K45: EC-10 (capitel estaca 60-L) | L45: 5.2 | M45: 5.3 | N45: 5 | O45: 5 | P45: =AVERAGE(L45:O45) -> 5.125 | Q45: =P45*10 -> 51.25
K46: EC-11 (capitel estaca 71-N) | L46: 5.3 | M46: 5.4 | N46: 5.3 | O46: 5.1 | P46: =AVERAGE(L46:O46) -> 5.275 | Q46: =P46*10 -> 52.75
K47: EC-12 (laje-PLE02) | L47: 5.2 | M47: 4.5 | N47: 4.9 | O47: 5 | P47: =AVERAGE(L47:O47) -> 4.9 | Q47: =P47*10 -> 49
... K49: EC-14 (túnel de descarga-PT03) | L49: 6.5 | M49: 5.5 | N49: 6.7 | O49: 7 | P49: =AVERAGE(L49:O49) -> 6.425 | Q49: =P49*10 -> 64.25
...

Sheet TABELA_ESCLEROMETRIA Rev
AJ2: aE | AK2: 1
AI3: y = -1.343249E-10x6 + 3.420646E-08x5 - 3.490515E-06x4 + 1.792832E-04x3 - 4.704508E-03x2 + 5.401466E-02x + 4.752819E-01 | AP3: {=CHOOSE({1,2,3,4},AH6^3,AH6^2,AH6,1)} -> 19702.656 | AQ3: 729.48525 | AR3: 27.008985 | AS3: 1
D4: Área de Ensaio | E4: Índices Esclerométricos | U4: 1ª avaliação | X4: 2ª avaliação | AB4: Produndidade de carbonatação (mm) | AC4: =D4 -> Área de Ensaio | AD4: Direção/ Sentido do Golpe (graus) | AE4: Índice escleromé-trico R | AF4: Coeficiente de correção k (calibração) | AG4: Correção em R devido à calibração (coef. k) | AH4: Resistência à compressão (descons. carbonatação) fc(MPa) | AI4: Redução em fc devido a carbona-tação | AJ4: Resist à compr. corrigida fc (MPa) | AK4: Módulo de elasticdade (Gpa) NBR6118 | AP4: =$AH$6^3 -> 19702.656 | AQ4: =$AH$6^2 -> 729.48525 | AR4: =$AH$6^1 -> 27.008985 | AS4: 1
E5: 1 | F5: 2 | G5: 3 | H5: 4 | I5: 5 | J5: 6 | K5: 7 | L5: 8 | M5: 9 | N5: 10 | O5: 11 | P5: 12 | Q5: 13 | R5: 14 | S5: 15 | T5: 16 | U5: Média inicial | V5: Limite inferior (0,9*média) | W5: Limite superior (1,1*média) | X5: Média Final | Y5: Limite inferior (0,9*média) | Z5: Limite superior (1,1*média) | AM5: coeficientes | AQ5: Impacto | AR5: Aferição 01 | AS5: Aferição 02
D6: ES-01 (túnel de descarga-PT05) | E6: 30 | F6: 32 | G6: 32 | H6: 33 | I6: 34 | J6: 34 | K6: 35 | L6: 36 | M6: 36 | N6: 36 | O6: 36 | P6: 36 | Q6: 36 | R6: 37 | S6: 37 | T6: 37 | U6: =AVERAGE(E6:T6) -> 34.8125 | V6: =U6*0.9 -> 31.33125 | W6: =U6*1.1 -> 38.29375 | X6: =AVERAGEIFS(E6:T6,E6:T6,">"&V6, E6:T6, "<"&W6) -> 35.133333 | Y6: =X6*0.9 -> 31.62 | Z6: =X6*1.1 -> 38.646667 | AB6: 49 | AC6: =D6 -> ES-01 (túnel de descarga-PT05) | AD6: 0 | AE6: =X6 -> 35.133333 | AF6: =$AR$20 -> 0.98039216 | AG6: =AE6*AF6 -> 34.444444 | AH6: =SUMPRODUCT(INDEX(Curvas!$B$3:$E$5,MATCH(AD6,Curvas!$A$3:$A$5,0),0),CHOOSE({1,2,3,4},AG6^3,AG6^2,AG6,1)) -> 27.008985 | AI6: {=SUMPRODUCT(TRANSPOSE($AM$6:$AM$12),CHOOSE({1,2,3,4,5,6,7},AH6^6,AH6^5,AH6^4,AH6^3,AH6^2,AH6,1))} -> 0.61667419 | AJ6: =AH6*AI6 -> 16.655744 | AK6: =$AK$2*5600*SQRT($AJ6)/1000 -> 22.854412 | AM6: -1.343249e-10 | AN6: a6 | AP6: =SUMPRODUCT(INDEX(Curvas!$B$3:$E$5,MATCH(AD6,Curvas!$A$3:$A$5,0),0),CHOOSE({1,2,3,4},AG6^3,AG6^2,AG6,1)) -> 27.008985 | AQ6: 1 | AR6: 81 | AS6: 82
D7: ES-02 (túnel de descarga-PT03) | E7: 30 | F7: 30 | G7: 30 | H7: 30 | I7: 30 | J7: 30 | K7: 31 | L7: 31 | M7: 31 | N7: 31 | O7: 32 | P7: 32 | Q7: 32 | R7: 32 | S7: 32 | T7: 32 | U7: =AVERAGE(E7:T7) -> 31 | V7: =U7*0.9 -> 27.9 | W7: =U7*1.1 -> 34.1 | X7: =AVERAGEIFS(E7:T7,E7:T7,">"&V7, E7:T7, "<"&W7) -> 31 | Y7: =X7*0.9 -> 27.9 | Z7: =X7*1.1 -> 34.1 | AB7: 59.3 | AC7: =D7 -> ES-02 (túnel de descarga-PT03) | AD7: 0 | AE7: =X7 -> 31 | AF7: =$AR$20 -> 0.98039216 | AG7: =AE7*AF7 -> 30.392157 | AH7: =SUMPRODUCT(INDEX(Curvas!$B$3:$E$5,MATCH(AD7,Curvas!$A$3:$A$5,0),0),CHOOSE({1,2,3,4},AG7^3,AG7^2,AG7,1)) -> 21.479964 | AI7: {=SUMPRODUCT(TRANSPOSE($AM$6:$AM$12),CHOOSE({1,2,3,4,5,6,7},AH7^6,AH7^5,AH7^4,AH7^3,AH7^2,AH7,1))} -> 0.64187521 | AJ7: =AH7*AI7 -> 13.787456 | AK7: =$AK$2*5600*SQRT($AJ7)/1000 -> 20.79362 | AM7: 3.420646e-08 | AN7: a5 | AP7: =SUMPRODUCT(INDEX(Curvas!$B$3:$E$5,MATCH(AD7,Curvas!$A$3:$A$5,0),0),CHOOSE({1,2,3,4},AG7^3,AG7^2,AG7,1)) -> 21.479964 | AQ7: 2 | AR7: 82 | AS7: 82
D8: ES-03 (túnel de descarga-PT06) | E8: 27 | F8: 30 | G8: 31 | H8: 31 | I8: 31 | J8: 31 | K8: 32 | L8: 32 | M8: 32 | N8: 33 | O8: 33 | P8: 34 | Q8: 34 | R8: 37 | S8: 39 | T8: 39 | U8: =AVERAGE(E8:T8) -> 32.875 | V8: =U8*0.9 -> 29.5875 | W8: =U8*1.1 -> 36.1625 | X8: =AVERAGEIFS(E8:T8,E8:T8,">"&V8, E8:T8, "<"&W8) -> 32 | Y8: =X8*0.9 -> 28.8 | Z8: =X8*1.1 -> 35.2 | AB8: 64.3 | AC8: =D8 -> ES-03 (túnel de descarga-PT06) | AD8: 0 | AE8: =X8 -> 32 | AF8: =$AR$20 -> 0.98039216 | AG8: =AE8*AF8 -> 31.372549 | AH8: =SUMPRODUCT(INDEX(Curvas!$B$3:$E$5,MATCH(AD8,Curvas!$A$3:$A$5,0),0),CHOOSE({1,2,3,4},AG8^3,AG8^2,AG8,1)) -> 22.801874 | AI8: {=SUMPRODUCT(TRANSPOSE($AM$6:$AM$12),CHOOSE({1,2,3,4,5,6,7},AH8^6,AH8^5,AH8^4,AH8^3,AH8^2,AH8,1))} -> 0.63477559 | AJ8: =AH8*AI8 -> 14.474073 | AK8: =$AK$2*5600*SQRT($AJ8)/1000 -> 21.305091 | AM8: -3.490515e-06 | AN8: a4 | AP8: =SUMPRODUCT(INDEX(Curvas!$B$3:$E$5,MATCH(AD8,Curvas!$A$3:$A$5,0),0),CHOOSE({1,2,3,4},AG8^3,AG8^2,AG8,1)) -> 22.801874 | AQ8: 3 | AR8: 81 | AS8: 81
D9: ES-04 (estaca 71-N) | E9: 33 | F9: 33 | G9: 34 | H9: 34 | I9: 36 | J9: 36 | K9: 37 | L9: 37 | M9: 37 | N9: 37 | O9: 38 | P9: 38 | Q9: 39 | R9: 39 | S9: 40 | T9: 48 | U9: =AVERAGE(E9:T9) -> 37.25 | V9: =U9*0.9 -> 33.525 | W9: =U9*1.1 -> 40.975 | X9: =AVERAGEIFS(E9:T9,E9:T9,">"&V9, E9:T9, "<"&W9) -> 37.076923 | Y9: =X9*0.9 -> 33.369231 | Z9: =X9*1.1 -> 40.784615 | AB9: 49.5 | AC9: =D9 -> ES-04 (estaca 71-N) | AD9: 0 | AE9: =X9 -> 37.076923 | AF9: =$AR$20 -> 0.98039216 | AG9: =AE9*AF9 -> 36.349925 | AH9: =SUMPRODUCT(INDEX(Curvas!$B$3:$E$5,MATCH(AD9,Curvas!$A$3:$A$5,0),0),CHOOSE({1,2,3,4},AG9^3,AG9^2,AG9,1)) -> 29.675152 | AI9: {=SUMPRODUCT(TRANSPOSE($AM$6:$AM$12),CHOOSE({1,2,3,4,5,6,7},AH9^6,AH9^5,AH9^4,AH9^3,AH9^2,AH9,1))} -> 0.60902724 | AJ9: =AH9*AI9 -> 18.072976 | AK9: =$AK$2*5600*SQRT($AJ9)/1000 -> 23.806901 | AM9: 0.0001792832 | AN9: a3 | AP9: =SUMPRODUCT(INDEX(Curvas!$B$3:$E$5,MATCH(AD9,Curvas!$A$3:$A$5,0),0),CHOOSE({1,2,3,4},AG9^3,AG9^2,AG9,1)) -> 29.675152 | AQ9: 4 | AR9: 82 | AS9: 82
D10: ES-05 (estaca 71-O) | E10: 31 | F10: 34 | G10: 34 | H10: 35 | I10: 35 | J10: 36 | K10: 36 | L10: 36 | M10: 36 | N10: 38 | O10: 38 | P10: 38 | Q10: 38 | R10: 39 | S10: 44 | T10: 48 | U10: =AVERAGE(E10:T10) -> 37.25 | V10: =U10*0.9 -> 33.525 | W10: =U10*1.1 -> 40.975 | X10: =AVERAGEIFS(E10:T10,E10:T10,">"&V10, E10:T10, "<"&W10) -> 36.384615 | Y10: =X10*0.9 -> 32.746154 | Z10: =X10*1.1 -> 40.023077 | AB10: 50.5 | AC10: =D10 -> ES-05 (estaca 71-O) | AD10: 0 | AE10: =X10 -> 36.384615 | AF10: =$AR$20 -> 0.98039216 | AG10: =AE10*AF10 -> 35.671192 | AH10: =SUMPRODUCT(INDEX(Curvas!$B$3:$E$5,MATCH(AD10,Curvas!$A$3:$A$5,0),0),CHOOSE({1,2,3,4},AG10^3,AG10^2,AG10,1)) -> 28.720063 | AI10: {=SUMPRODUCT(TRANSPOSE($AM$6:$AM$12),CHOOSE({1,2,3,4,5,6,7},AH10^6,AH10^5,AH10^4,AH10^3,AH10^2,AH10,1))} -> 0.61143617 | AJ10: =AH10*AI10 -> 17.560485 | AK10: =$AK$2*5600*SQRT($AJ10)/1000 -> 23.46693 | AM10: -0.004704508 | AN10: a2 | AP10: =SUMPRODUCT(INDEX(Curvas!$B$3:$E$5,MATCH(AD10,Curvas!$A$3:$A$5,0),0),CHOOSE({1,2,3,4},AG10^3,AG10^2,AG10,1)) -> 28.720063 | AQ10: 5 | AR10: 82 | AS10: 81
D11: ES-06 (estaca 71-S) | E11: 35 | F11: 35 | G11: 36 | H11: 36 | I11: 37 | J11: 38 | K11: 38 | L11: 38 | M11: 41 | N11: 41 | O11: 42 | P11: 42 | Q11: 44 | R11: 45 | S11: 53 | T11: 58 | U11: =AVERAGE(E11:T11) -> 41.1875 | V11: =U11*0.9 -> 37.06875 | W11: =U11*1.1 -> 45.30625 | X11: =AVERAGEIFS(E11:T11,E11:T11,">"&V11, E11:T11, "<"&W11) -> 41 | Y11: =X11*0.9 -> 36.9 | Z11: =X11*1.1 -> 45.1 | AB11: 55 | AC11: =D11 -> ES-06 (estaca 71-S) | AD11: 0 | AE11: =X11 -> 41 | AF11: =$AR$20 -> 0.98039216 | AG11: =AE11*AF11 -> 40.196078 | AH11: =SUMPRODUCT(INDEX(Curvas!$B$3:$E$5,MATCH(AD11,Curvas!$A$3:$A$5,0),0),CHOOSE({1,2,3,4},AG11^3,AG11^2,AG11,1)) -> 35.212386 | AI11: {=SUMPRODUCT(TRANSPOSE($AM$6:$AM$12),CHOOSE({1,2,3,4,5,6,7},AH11^6,AH11^5,AH11^4,AH11^3,AH11^2,AH11,1))} -> 0.60109749 | AJ11: =AH11*AI11 -> 21.166077 | AK11: =$AK$2*5600*SQRT($AJ11)/1000 -> 25.763699 | AM11: 0.05401466 | AN11: a1 | AP11: =SUMPRODUCT(INDEX(Curvas!$B$3:$E$5,MATCH(AD11,Curvas!$A$3:$A$5,0),0),CHOOSE({1,2,3,4},AG11^3,AG11^2,AG11,1)) -> 35.212386 | AQ11: 6 | AR11: 82 | AS11: 82
D12: ES-07 (estaca 71-L) | E12: 31 | F12: 35 | G12: 36 | H12: 36 | I12: 37 | J12: 37 | K12: 38 | L12: 38 | M12: 38 | N12: 39 | O12: 39 | P12: 40 | Q12: 41 | R12: 41 | S12: 45 | T12: 46 | U12: =AVERAGE(E12:T12) -> 38.5625 | V12: =U12*0.9 -> 34.70625 | W12: =U12*1.1 -> 42.41875 | X12: =AVERAGEIFS(E12:T12,E12:T12,">"&V12, E12:T12, "<"&W12) -> 38.076923 | Y12: =X12*0.9 -> 34.269231 | Z12: =X12*1.1 -> 41.884615 | AB12: 57 | AC12: =D12 -> ES-07 (estaca 71-L) | AD12: 0 | AE12: =X12 -> 38.076923 | AF12: =$AR$20 -> 0.98039216 | AG12: =AE12*AF12 -> 37.330317 | AH12: =SUMPRODUCT(INDEX(Curvas!$B$3:$E$5,MATCH(AD12,Curvas!$A$3:$A$5,0),0),CHOOSE({1,2,3,4},AG12^3,AG12^2,AG12,1)) -> 31.065845 | AI12: {=SUMPRODUCT(TRANSPOSE($AM$6:$AM$12),CHOOSE({1,2,3,4,5,6,7},AH12^6,AH12^5,AH12^4,AH12^3,AH12^2,AH12,1))} -> 0.60613263 | AJ12: =AH12*AI12 -> 18.830022 | AK12: =$AK$2*5600*SQRT($AJ12)/1000 -> 24.300401 | AM12: 0.4752819 | AN12: a0 | AP12: =SUMPRODUCT(INDEX(Curvas!$B$3:$E$5,MATCH(AD12,Curvas!$A$3:$A$5,0),0),CHOOSE({1,2,3,4},AG12^3,AG12^2,AG12,1)) -> 31.065845 | AQ12: 7 | AR12: 81 | AS12: 82
D13: ES-08 (estaca 60-N) | E13: 26 | F13: 27 | G13: 28 | H13: 29 | I13: 30 | J13: 30 | K13: 32 | L13: 32 | M13: 32 | N13: 33 | O13: 33 | P13: 34 | Q13: 35 | R13: 36 | S13: 36 | T13: 37 | U13: =AVERAGE(E13:T13) -> 31.875 | V13: =U13*0.9 -> 28.6875 | W13: =U13*1.1 -> 35.0625 | X13: =AVERAGEIFS(E13:T13,E13:T13,">"&V13, E13:T13, "<"&W13) -> 32 | Y13: =X13*0.9 -> 28.8 | Z13: =X13*1.1 -> 35.2 | AB13: 70 | AC13: =D13 -> ES-08 (estaca 60-N) | AD13: 0 | AE13: =X13 -> 32 | AF13: =$AR$20 -> 0.98039216 | AG13: =AE13*AF13 -> 31.372549 | AH13: =SUMPRODUCT(INDEX(Curvas!$B$3:$E$5,MATCH(AD13,Curvas!$A$3:$A$5,0),0),CHOOSE({1,2,3,4},AG13^3,AG13^2,AG13,1)) -> 22.801874 | AI13: {=SUMPRODUCT(TRANSPOSE($AM$6:$AM$12),CHOOSE({1,2,3,4,5,6,7},AH13^6,AH13^5,AH13^4,AH13^3,AH13^2,AH13,1))} -> 0.63477559 | AJ13: =AH13*AI13 -> 14.474073 | AK13: =$AK$2*5600*SQRT($AJ13)/1000 -> 21.305091 | AP13: =SUMPRODUCT(INDEX(Curvas!$B$3:$E$5,MATCH(AD13,Curvas!$A$3:$A$5,0),0),CHOOSE({1,2,3,4},AG13^3,AG13^2,AG13,1)) -> 22.801874 | AQ13: 8 | AR13: 82 | AS13: 81
D14: ES-09 (estaca 60-O) | E14: 29 | F14: 30 | G14: 30 | H14: 30 | I14: 30 | J14: 31 | K14: 31 | L14: 32 | M14: 32 | N14: 32 | O14: 33 | P14: 34 | Q14: 35 | R14: 35 | S14: 36 | T14: 36 | U14: =AVERAGE(E14:T14) -> 32.25 | V14: =U14*0.9 -> 29.025 | W14: =U14*1.1 -> 35.475 | X14: =AVERAGEIFS(E14:T14,E14:T14,">"&V14, E14:T14, "<"&W14) -> 31.923077 | Y14: =X14*0.9 -> 28.730769 | Z14: =X14*1.1 -> 35.115385 | AB14: 62 | AC14: =D14 -> ES-09 (estaca 60-O) | AD14: 0 | AE14: =X14 -> 31.923077 | AF14: =$AR$20 -> 0.98039216 | AG14: =AE14*AF14 -> 31.297134 | AH14: =SUMPRODUCT(INDEX(Curvas!$B$3:$E$5,MATCH(AD14,Curvas!$A$3:$A$5,0),0),CHOOSE({1,2,3,4},AG14^3,AG14^2,AG14,1)) -> 22.699857 | AI14: {=SUMPRODUCT(TRANSPOSE($AM$6:$AM$12),CHOOSE({1,2,3,4,5,6,7},AH14^6,AH14^5,AH14^4,AH14^3,AH14^2,AH14,1))} -> 0.63530232 | AJ14: =AH14*AI14 -> 14.421272 | AK14: =$AK$2*5600*SQRT($AJ14)/1000 -> 21.266196 | AP14: =SUMPRODUCT(INDEX(Curvas!$B$3:$E$5,MATCH(AD14,Curvas!$A$3:$A$5,0),0),CHOOSE({1,2,3,4},AG14^3,AG14^2,AG14,1)) -> 22.699857 | AQ14: 9 | AR14: 82 | AS14: 82
D15: ES-10 (estaca 60-S) | E15: 30 | F15: 30 | G15: 31 | H15: 32 | I15: 32 | J15: 32 | K15: 33 | L15: 33 | M15: 33 | N15: 34 | O15: 34 | P15: 35 | Q15: 35 | R15: 35 | S15: 37 | T15: 38 | U15: =AVERAGE(E15:T15) -> 33.375 | V15: =U15*0.9 -> 30.0375 | W15: =U15*1.1 -> 36.7125 | X15: =AVERAGEIFS(E15:T15,E15:T15,">"&V15, E15:T15, "<"&W15) -> 33.25 | Y15: =X15*0.9 -> 29.925 | Z15: =X15*1.1 -> 36.575 | AB15: 6 | AC15: =D15 -> ES-10 (estaca 60-S) | AD15: 0 | AE15: =X15 -> 33.25 | AF15: =$AR$20 -> 0.98039216 | AG15: =AE15*AF15 -> 32.598039 | AH15: =SUMPRODUCT(INDEX(Curvas!$B$3:$E$5,MATCH(AD15,Curvas!$A$3:$A$5,0),0),CHOOSE({1,2,3,4},AG15^3,AG15^2,AG15,1)) -> 24.467795 | AI15: {=SUMPRODUCT(TRANSPOSE($AM$6:$AM$12),CHOOSE({1,2,3,4,5,6,7},AH15^6,AH15^5,AH15^4,AH15^3,AH15^2,AH15,1))} -> 0.62673504 | AJ15: =AH15*AI15 -> 15.334824 | AK15: =$AK$2*5600*SQRT($AJ15)/1000 -> 21.929434 | AP15: =SUMPRODUCT(INDEX(Curvas!$B$3:$E$5,MATCH(AD15,Curvas!$A$3:$A$5,0),0),CHOOSE({1,2,3,4},AG15^3,AG15^2,AG15,1)) -> 24.467795 | AQ15: 10 | AR15: 81 | AS15: 82
D16: ES-11 (estaca 60-L) | E16: 30 | F16: 30 | G16: 31 | H16: 32 | I16: 32 | J16: 32 | K16: 33 | L16: 33 | M16: 33 | N16: 33 | O16: 34 | P16: 34 | Q16: 34 | R16: 34 | S16: 37 | T16: 39 | U16: =AVERAGE(E16:T16) -> 33.1875 | V16: =U16*0.9 -> 29.86875 | W16: =U16*1.1 -> 36.50625 | X16: =AVERAGEIFS(E16:T16,E16:T16,">"&V16, E16:T16, "<"&W16) -> 32.5 | Y16: =X16*0.9 -> 29.25 | Z16: =X16*1.1 -> 35.75 | AB16: 6 | AC16: =D16 -> ES-11 (estaca 60-L) | AD16: 0 | AE16: =X16 -> 32.5 | AF16: =$AR$20 -> 0.98039216 | AG16: =AE16*AF16 -> 31.862745 | AH16: =SUMPRODUCT(INDEX(Curvas!$B$3:$E$5,MATCH(AD16,Curvas!$A$3:$A$5,0),0),CHOOSE({1,2,3,4},AG16^3,AG16^2,AG16,1)) -> 23.466373 | AI16: {=SUMPRODUCT(TRANSPOSE($AM$6:$AM$12),CHOOSE({1,2,3,4,5,6,7},AH16^6,AH16^5,AH16^4,AH16^3,AH16^2,AH16,1))} -> 0.63143882 | AJ16: =AH16*AI16 -> 14.817579 | AK16: =$AK$2*5600*SQRT($AJ16)/1000 -> 21.556421 | AP16: =SUMPRODUCT(INDEX(Curvas!$B$3:$E$5,MATCH(AD16,Curvas!$A$3:$A$5,0),0),CHOOSE({1,2,3,4},AG16^3,AG16^2,AG16,1)) -> 23.466373 | AQ16: somatório | AR16: =SUM(AR6:AR15) -> 816 | AS16: =SUM(AS6:AS15) -> 817
D17: ES-12 (estaca 44-N) | E17: 28 | F17: 30 | G17: 30 | H17: 30 | I17: 30 | J17: 32 | K17: 32 | L17: 32 | M17: 32 | N17: 32 | O17: 32 | P17: 33 | Q17: 33 | R17: 37 | S17: 39 | T17: 40 | U17: =AVERAGE(E17:T17) -> 32.625 | V17: =U17*0.9 -> 29.3625 | W17: =U17*1.1 -> 35.8875 | X17: =AVERAGEIFS(E17:T17,E17:T17,">"&V17, E17:T17, "<"&W17) -> 31.5 | Y17: =X17*0.9 -> 28.35 | Z17: =X17*1.1 -> 34.65 | AB17: 64.8 | AC17: =D17 -> ES-12 (estaca 44-N) | AD17: 0 | AE17: =X17 -> 31.5 | AF17: =$AR$20 -> 0.98039216 | AG17: =AE17*AF17 -> 30.882353 | AH17: =SUMPRODUCT(INDEX(Curvas!$B$3:$E$5,MATCH(AD17,Curvas!$A$3:$A$5,0),0),CHOOSE({1,2,3,4},AG17^3,AG17^2,AG17,1)) -> 22.139766 | AI17: {=SUMPRODUCT(TRANSPOSE($AM$6:$AM$12),CHOOSE({1,2,3,4,5,6,7},AH17^6,AH17^5,AH17^4,AH17^3,AH17^2,AH17,1))} -> 0.6382593 | AJ17: =AH17*AI17 -> 14.130912 | AK17: =$AK$2*5600*SQRT($AJ17)/1000 -> 21.051019 | AP17: =SUMPRODUCT(INDEX(Curvas!$B$3:$E$5,MATCH(AD17,Curvas!$A$3:$A$5,0),0),CHOOSE({1,2,3,4},AG17^3,AG17^2,AG17,1)) -> 22.139766 | AQ17: número de impactos | AR17: =COUNT(AR6:AR15) -> 10 | AS17: =COUNT(AS6:AS15) -> 10
D18: ES-13 (estaca 44-O) | E18: 25 | F18: 29 | G18: 30 | H18: 32 | I18: 32 | J18: 32 | K18: 32 | L18: 32 | M18: 32 | N18: 32 | O18: 32 | P18: 33 | Q18: 34 | R18: 34 | S18: 35 | T18: 38 | U18: =AVERAGE(E18:T18) -> 32.125 | V18: =U18*0.9 -> 28.9125 | W18: =U18*1.1 -> 35.3375 | X18: =AVERAGEIFS(E18:T18,E18:T18,">"&V18, E18:T18, "<"&W18) -> 32.214286 | Y18: =X18*0.9 -> 28.992857 | Z18: =X18*1.1 -> 35.435714 | AB18: 6 | AC18: =D18 -> ES-13 (estaca 44-O) | AD18: 0 | AE18: =X18 -> 32.214286 | AF18: =$AR$20 -> 0.98039216 | AG18: =AE18*AF18 -> 31.582633 | AH18: =SUMPRODUCT(INDEX(Curvas!$B$3:$E$5,MATCH(AD18,Curvas!$A$3:$A$5,0),0),CHOOSE({1,2,3,4},AG18^3,AG18^2,AG18,1)) -> 23.086361 | AI18: {=SUMPRODUCT(TRANSPOSE($AM$6:$AM$12),CHOOSE({1,2,3,4,5,6,7},AH18^6,AH18^5,AH18^4,AH18^3,AH18^2,AH18,1))} -> 0.63332678 | AJ18: =AH18*AI18 -> 14.621211 | AK18: =$AK$2*5600*SQRT($AJ18)/1000 -> 21.413107 | AP18: =SUMPRODUCT(INDEX(Curvas!$B$3:$E$5,MATCH(AD18,Curvas!$A$3:$A$5,0),0),CHOOSE({1,2,3,4},AG18^3,AG18^2,AG18,1)) -> 23.086361 | AQ18: Índice esclerométrico nominal | AR18: 80 | AS18: 80
D19: ES-14 (estaca 44-S) | E19: 29 | F19: 30 | G19: 30 | H19: 30 | I19: 31 | J19: 31 | K19: 32 | L19: 32 | M19: 33 | N19: 33 | O19: 34 | P19: 34 | Q19: 35 | R19: 35 | S19: 38 | T19: 47 | U19: =AVERAGE(E19:T19) -> 33.375 | V19: =U19*0.9 -> 30.0375 | W19: =U19*1.1 -> 36.7125 | X19: =AVERAGEIFS(E19:T19,E19:T19,">"&V19, E19:T19, "<"&W19) -> 33 | Y19: =X19*0.9 -> 29.7 | Z19: =X19*1.1 -> 36.3 | AB19: 6 | AC19: =D19 -> ES-14 (estaca 44-S) | AD19: 0 | AE19: =X19 -> 33 | AF19: =$AR$20 -> 0.98039216 | AG19: =AE19*AF19 -> 32.352941 | AH19: =SUMPRODUCT(INDEX(Curvas!$B$3:$E$5,MATCH(AD19,Curvas!$A$3:$A$5,0),0),CHOOSE({1,2,3,4},AG19^3,AG19^2,AG19,1)) -> 24.13335 | AI19: {=SUMPRODUCT(TRANSPOSE($AM$6:$AM$12),CHOOSE({1,2,3,4,5,6,7},AH19^6,AH19^5,AH19^4,AH19^3,AH19^2,AH19,1))} -> 0.62826112 | AJ19: =AH19*AI19 -> 15.162045 | AK19: =$AK$2*5600*SQRT($AJ19)/1000 -> 21.805544 | AP19: =SUMPRODUCT(INDEX(Curvas!$B$3:$E$5,MATCH(AD19,Curvas!$A$3:$A$5,0),0),CHOOSE({1,2,3,4},AG19^3,AG19^2,AG19,1)) -> 24.13335
D20: ES-15 (estaca 44-L) | E20: 26 | F20: 29 | G20: 29 | H20: 29 | I20: 29 | J20: 29 | K20: 30 | L20: 30 | M20: 30 | N20: 30 | O20: 30 | P20: 31 | Q20: 32 | R20: 33 | S20: 34 | T20: 36 | U20: =AVERAGE(E20:T20) -> 30.4375 | V20: =U20*0.9 -> 27.39375 | W20: =U20*1.1 -> 33.48125 | X20: =AVERAGEIFS(E20:T20,E20:T20,">"&V20, E20:T20, "<"&W20) -> 30.076923 | Y20: =X20*0.9 -> 27.069231 | Z20: =X20*1.1 -> 33.084615 | AB20: 6 | AC20: =D20 -> ES-15 (estaca 44-L) | AD20: 0 | AE20: =X20 -> 30.076923 | AF20: =$AR$20 -> 0.98039216 | AG20: =AE20*AF20 -> 29.487179 | AH20: =SUMPRODUCT(INDEX(Curvas!$B$3:$E$5,MATCH(AD20,Curvas!$A$3:$A$5,0),0),CHOOSE({1,2,3,4},AG20^3,AG20^2,AG20,1)) -> 20.267634 | AI20: {=SUMPRODUCT(TRANSPOSE($AM$6:$AM$12),CHOOSE({1,2,3,4,5,6,7},AH20^6,AH20^5,AH20^4,AH20^3,AH20^2,AH20,1))} -> 0.64883695 | AJ20: =AH20*AI20 -> 13.15039 | AK20: =$AK$2*5600*SQRT($AJ20)/1000 -> 20.307541 | AP20: =SUMPRODUCT(INDEX(Curvas!$B$3:$E$5,MATCH(AD20,Curvas!$A$3:$A$5,0),0),CHOOSE({1,2,3,4},AG20^3,AG20^2,AG20,1)) -> 20.267634 | AQ20: coeficiente de correção k | AR20: =AR17*AR18/AR16 -> 0.98039216 | AS20: =AS17*AS18/AS16 -> 0.97919217
D21: ES-16b (estaca 24-N) | E21: 20 | F21: 30 | G21: 31 | H21: 31 | I21: 31 | J21: 32 | K21: 32 | L21: 32 | M21: 32 | N21: 32 | O21: 32 | P21: 32 | Q21: 34 | R21: 34 | S21: 36 | T21: 38 | U21: =AVERAGE(E21:T21) -> 31.8125 | V21: =U21*0.9 -> 28.63125 | W21: =U21*1.1 -> 34.99375 | X21: =AVERAGEIFS(E21:T21,E21:T21,">"&V21, E21:T21, "<"&W21) -> 31.923077 | Y21: =X21*0.9 -> 28.730769 | Z21: =X21*1.1 -> 35.115385 | AB21: 65.8 | AC21: =D21 -> ES-16b (estaca 24-N) | AD21: 0 | AE21: =X21 -> 31.923077 | AF21: =$AS$20 -> 0.97919217 | AG21: =AE21*AF21 -> 31.258827 | AH21: =SUMPRODUCT(INDEX(Curvas!$B$3:$E$5,MATCH(AD21,Curvas!$A$3:$A$5,0),0),CHOOSE({1,2,3,4},AG21^3,AG21^2,AG21,1)) -> 22.648059 | AI21: {=SUMPRODUCT(TRANSPOSE($AM$6:$AM$12),CHOOSE({1,2,3,4,5,6,7},AH21^6,AH21^5,AH21^4,AH21^3,AH21^2,AH21,1))} -> 0.63557119 | AJ21: =AH21*AI21 -> 14.394454 | AK21: =$AK$2*5600*SQRT($AJ21)/1000 -> 21.246413 | AP21: =SUMPRODUCT(INDEX(Curvas!$B$3:$E$5,MATCH(AD21,Curvas!$A$3:$A$5,0),0),CHOOSE({1,2,3,4},AG21^3,AG21^2,AG21,1)) -> 22.648059
D22: ES-17b (estaca 24-S) | E22: 32 | F22: 32 | G22: 33 | H22: 33 | I22: 33 | J22: 34 | K22: 34 | L22: 34 | M22: 34 | N22: 34 | O22: 35 | P22: 35 | Q22: 36 | R22: 36 | S22: 40 | T22: 42 | U22: =AVERAGE(E22:T22) -> 34.8125 | V22: =U22*0.9 -> 31.33125 | W22: =U22*1.1 -> 38.29375 | X22: =AVERAGEIFS(E22:T22,E22:T22,">"&V22, E22:T22, "<"&W22) -> 33.928571 | Y22: =X22*0.9 -> 30.535714 | Z22: =X22*1.1 -> 37.321429 | AB22: 6 | AC22: =D22 -> ES-17b (estaca 24-S) | AD22: 0 | AE22: =X22 -> 33.928571 | AF22: =$AS$20 -> 0.97919217 | AG22: =AE22*AF22 -> 33.222591 | AH22: =SUMPRODUCT(INDEX(Curvas!$B$3:$E$5,MATCH(AD22,Curvas!$A$3:$A$5,0),0),CHOOSE({1,2,3,4},AG22^3,AG22^2,AG22,1)) -> 25.322989 | AI22: {=SUMPRODUCT(TRANSPOSE($AM$6:$AM$12),CHOOSE({1,2,3,4,5,6,7},AH22^6,AH22^5,AH22^4,AH22^3,AH22^2,AH22,1))} -> 0.6230436 | AJ22: =AH22*AI22 -> 15.777327 | AK22: =$AK$2*5600*SQRT($AJ22)/1000 -> 22.243582 | AP22: =SUMPRODUCT(INDEX(Curvas!$B$3:$E$5,MATCH(AD22,Curvas!$A$3:$A$5,0),0),CHOOSE({1,2,3,4},AG22^3,AG22^2,AG22,1)) -> 25.322989
D23: ES-18 (estaca 24-L) | E23: 30 | F23: 32 | G23: 32 | H23: 32 | I23: 32 | J23: 33 | K23: 33 | L23: 34 | M23: 34 | N23: 34 | O23: 34 | P23: 36 | Q23: 36 | R23: 37 | S23: 37 | T23: 41 | U23: =AVERAGE(E23:T23) -> 34.1875 | V23: =U23*0.9 -> 30.76875 | W23: =U23*1.1 -> 37.60625 | X23: =AVERAGEIFS(E23:T23,E23:T23,">"&V23, E23:T23, "<"&W23) -> 34 | Y23: =X23*0.9 -> 30.6 | Z23: =X23*1.1 -> 37.4 | AB23: 6 | AC23: =D23 -> ES-18 (estaca 24-L) | AD23: 0 | AE23: =X23 -> 34 | AF23: =$AR$20 -> 0.98039216 | AG23: =AE23*AF23 -> 33.333333 | AH23: =SUMPRODUCT(INDEX(Curvas!$B$3:$E$5,MATCH(AD23,Curvas!$A$3:$A$5,0),0),CHOOSE({1,2,3,4},AG23^3,AG23^2,AG23,1)) -> 25.475083 | AI23: {=SUMPRODUCT(TRANSPOSE($AM$6:$AM$12),CHOOSE({1,2,3,4,5,6,7},AH23^6,AH23^5,AH23^4,AH23^3,AH23^2,AH23,1))} -> 0.62241932 | AJ23: =AH23*AI23 -> 15.856184 | AK23: =$AK$2*5600*SQRT($AJ23)/1000 -> 22.299101 | AP23: =SUMPRODUCT(INDEX(Curvas!$B$3:$E$5,MATCH(AD23,Curvas!$A$3:$A$5,0),0),CHOOSE({1,2,3,4},AG23^3,AG23^2,AG23,1)) -> 25.475083
D24: ES-19 (capitel estaca 71-N) | E24: 30 | F24: 31 | G24: 32 | H24: 32 | I24: 33 | J24: 34 | K24: 34 | L24: 34 | M24: 35 | N24: 35 | O24: 36 | P24: 36 | Q24: 36 | R24: 36 | S24: 36 | T24: 40 | U24: =AVERAGE(E24:T24) -> 34.375 | V24: =U24*0.9 -> 30.9375 | W24: =U24*1.1 -> 37.8125 | X24: =AVERAGEIFS(E24:T24,E24:T24,">"&V24, E24:T24, "<"&W24) -> 34.285714 | Y24: =X24*0.9 -> 30.857143 | Z24: =X24*1.1 -> 37.714286 | AB24: 51.3 | AC24: =D24 -> ES-19 (capitel estaca 71-N) | AD24: 0 | AE24: =X24 -> 34.285714 | AF24: =$AS$20 -> 0.97919217 | AG24: =AE24*AF24 -> 33.572303 | AH24: =SUMPRODUCT(INDEX(Curvas!$B$3:$E$5,MATCH(AD24,Curvas!$A$3:$A$5,0),0),CHOOSE({1,2,3,4},AG24^3,AG24^2,AG24,1)) -> 25.803762 | AI24: {=SUMPRODUCT(TRANSPOSE($AM$6:$AM$12),CHOOSE({1,2,3,4,5,6,7},AH24^6,AH24^5,AH24^4,AH24^3,AH24^2,AH24,1))} -> 0.62110381 | AJ24: =AH24*AI24 -> 16.026815 | AK24: =$AK$2*5600*SQRT($AJ24)/1000 -> 22.418762 | AP24: =SUMPRODUCT(INDEX(Curvas!$B$3:$E$5,MATCH(AD24,Curvas!$A$3:$A$5,0),0),CHOOSE({1,2,3,4},AG24^3,AG24^2,AG24,1)) -> 25.803762
D25: ES-20 (capitel estaca 71-S) | E25: 33 | F25: 34 | G25: 35 | H25: 35 | I25: 35 | J25: 36 | K25: 36 | L25: 36 | M25: 36 | N25: 36 | O25: 37 | P25: 38 | Q25: 38 | R25: 39 | S25: 39 | T25: 40 | U25: =AVERAGE(E25:T25) -> 36.4375 | V25: =U25*0.9 -> 32.79375 | W25: =U25*1.1 -> 40.08125 | X25: =AVERAGEIFS(E25:T25,E25:T25,">"&V25, E25:T25, "<"&W25) -> 36.4375 | Y25: =X25*0.9 -> 32.79375 | Z25: =X25*1.1 -> 40.08125 | AB25: 6 | AC25: =D25 -> ES-20 (capitel estaca 71-S) | AD25: 0 | AE25: =X25 -> 36.4375 | AF25: =$AS$20 -> 0.97919217 | AG25: =AE25*AF25 -> 35.679315 | AH25: =SUMPRODUCT(INDEX(Curvas!$B$3:$E$5,MATCH(AD25,Curvas!$A$3:$A$5,0),0),CHOOSE({1,2,3,4},AG25^3,AG25^2,AG25,1)) -> 28.731457 | AI25: {=SUMPRODUCT(TRANSPOSE($AM$6:$AM$12),CHOOSE({1,2,3,4,5,6,7},AH25^6,AH25^5,AH25^4,AH25^3,AH25^2,AH25,1))} -> 0.61140531 | AJ25: =AH25*AI25 -> 17.566566 | AK25: =$AK$2*5600*SQRT($AJ25)/1000 -> 23.470993 | AP25: =SUMPRODUCT(INDEX(Curvas!$B$3:$E$5,MATCH(AD25,Curvas!$A$3:$A$5,0),0),CHOOSE({1,2,3,4},AG25^3,AG25^2,AG25,1)) -> 28.731457 | AQ25: -0.00651333 | AR25: 1.4013221 | AS25: -18.520102
D26: ES-21 (capitel estaca 60-N) | E26: 32 | F26: 33 | G26: 33 | H26: 33 | I26: 34 | J26: 34 | K26: 34 | L26: 35 | M26: 36 | N26: 37 | O26: 37 | P26: 37 | Q26: 37 | R26: 38 | S26: 38 | T26: 39 | U26: =AVERAGE(E26:T26) -> 35.4375 | V26: =U26*0.9 -> 31.89375 | W26: =U26*1.1 -> 38.98125 | X26: =AVERAGEIFS(E26:T26,E26:T26,">"&V26, E26:T26, "<"&W26) -> 35.2 | Y26: =X26*0.9 -> 31.68 | Z26: =X26*1.1 -> 38.72 | AB26: 42.8 | AC26: =D26 -> ES-21 (capitel estaca 60-N) | AD26: 0 | AE26: =X26 -> 35.2 | AF26: =$AS$20 -> 0.97919217 | AG26: =AE26*AF26 -> 34.467564 | AH26: =SUMPRODUCT(INDEX(Curvas!$B$3:$E$5,MATCH(AD26,Curvas!$A$3:$A$5,0),0),CHOOSE({1,2,3,4},AG26^3,AG26^2,AG26,1)) -> 27.041058 | AI26: {=SUMPRODUCT(TRANSPOSE($AM$6:$AM$12),CHOOSE({1,2,3,4,5,6,7},AH26^6,AH26^5,AH26^4,AH26^3,AH26^2,AH26,1))} -> 0.61656476 | AJ26: =AH26*AI26 -> 16.672564 | AK26: =$AK$2*5600*SQRT($AJ26)/1000 -> 22.865948
D27: ES-22 (fundo da laje-PLE02) | E27: 37 | F27: 39 | G27: 40 | H27: 41 | I27: 42 | J27: 42 | K27: 42 | L27: 42 | M27: 43 | N27: 43 | O27: 43 | P27: 43 | Q27: 44 | R27: 44 | S27: 44 | T27: 44 | U27: =AVERAGE(E27:T27) -> 42.0625 | V27: =U27*0.9 -> 37.85625 | W27: =U27*1.1 -> 46.26875 | X27: =AVERAGEIFS(E27:T27,E27:T27,">"&V27, E27:T27, "<"&W27) -> 42.4 | Y27: =X27*0.9 -> 38.16 | Z27: =X27*1.1 -> 46.64 | AB27: 52.8 | AC27: =D27 -> ES-22 (fundo da laje-PLE02) | AD27: -90 | AE27: =X27 -> 42.4 | AF27: =$AS$20 -> 0.97919217 | AG27: =AE27*AF27 -> 41.517748 | AH27: =SUMPRODUCT(INDEX(Curvas!$B$3:$E$5,MATCH(AD27,Curvas!$A$3:$A$5,0),0),CHOOSE({1,2,3,4},AG27^3,AG27^2,AG27,1)) -> 30.890245 | AI27: {=SUMPRODUCT(TRANSPOSE($AM$6:$AM$12),CHOOSE({1,2,3,4,5,6,7},AH27^6,AH27^5,AH27^4,AH27^3,AH27^2,AH27,1))} -> 0.60646002 | AJ27: =AH27*AI27 -> 18.733699 | AK27: =$AK$2*5600*SQRT($AJ27)/1000 -> 24.238168 | BD27: Resistência à compressão (descons. carbonatação) fck(MPa) | BE27: Redução em fck devido a carbona-tação
D28: ES-23 (bloco de fundação-CP08) | E28: 38 | F28: 39 | G28: 40 | H28: 41 | I28: 42 | J28: 42 | K28: 42 | L28: 43 | M28: 43 | N28: 43 | O28: 43 | P28: 44 | Q28: 44 | R28: 45 | S28: 46 | T28: 47 | U28: =AVERAGE(E28:T28) -> 42.625 | V28: =U28*0.9 -> 38.3625 | W28: =U28*1.1 -> 46.8875 | X28: =AVERAGEIFS(E28:T28,E28:T28,">"&V28, E28:T28, "<"&W28) -> 42.642857 | Y28: =X28*0.9 -> 38.378571 | Z28: =X28*1.1 -> 46.907143 | AB28: 6 | AC28: =D28 -> ES-23 (bloco de fundação-CP08) | AD28: 0 | AE28: =X28 -> 42.642857 | AF28: =$AS$20 -> 0.97919217 | AG28: =AE28*AF28 -> 41.755552 | AH28: =SUMPRODUCT(INDEX(Curvas!$B$3:$E$5,MATCH(AD28,Curvas!$A$3:$A$5,0),0),CHOOSE({1,2,3,4},AG28^3,AG28^2,AG28,1)) -> 37.52437 | AI28: {=SUMPRODUCT(TRANSPOSE($AM$6:$AM$12),CHOOSE({1,2,3,4,5,6,7},AH28^6,AH28^5,AH28^4,AH28^3,AH28^2,AH28,1))} -> 0.59999468 | AJ28: =AH28*AI28 -> 22.514422 | AK28: =$AK$2*5600*SQRT($AJ28)/1000 -> 26.571644
D29: ES-24 (fundo da laje-PLE04) | E29: 42 | F29: 46 | G29: 46 | H29: 46 | I29: 46 | J29: 47 | K29: 47 | L29: 48 | M29: 48 | N29: 48 | O29: 48 | P29: 48 | Q29: 49 | R29: 50 | S29: 50 | T29: 55 | U29: =AVERAGE(E29:T29) -> 47.75 | V29: =U29*0.9 -> 42.975 | W29: =U29*1.1 -> 52.525 | X29: =AVERAGEIFS(E29:T29,E29:T29,">"&V29, E29:T29, "<"&W29) -> 47.642857 | Y29: =X29*0.9 -> 42.878571 | Z29: =X29*1.1 -> 52.407143 | AB29: 6 | AC29: =D29 -> ES-24 (fundo da laje-PLE04) | AD29: -90 | AE29: =X29 -> 47.642857 | AF29: =$AS$20 -> 0.97919217 | AG29: =AE29*AF29 -> 46.651513 | AH29: =SUMPRODUCT(INDEX(Curvas!$B$3:$E$5,MATCH(AD29,Curvas!$A$3:$A$5,0),0),CHOOSE({1,2,3,4},AG29^3,AG29^2,AG29,1)) -> 38.532331 | AI29: {=SUMPRODUCT(TRANSPOSE($AM$6:$AM$12),CHOOSE({1,2,3,4,5,6,7},AH29^6,AH29^5,AH29^4,AH29^3,AH29^2,AH29,1))} -> 0.59976184 | AJ29: =AH29*AI29 -> 23.110222 | AK29: =$AK$2*5600*SQRT($AJ29)/1000 -> 26.920931
D30: ES-25 (fundo da laje-PLE03) | E30: 41 | F30: 41 | G30: 41 | H30: 42 | I30: 42 | J30: 43 | K30: 44 | L30: 44 | M30: 44 | N30: 46 | O30: 48 | P30: 48 | Q30: 48 | R30: 50 | S30: 50 | T30: 50 | U30: =AVERAGE(E30:T30) -> 45.125 | V30: =U30*0.9 -> 40.6125 | W30: =U30*1.1 -> 49.6375 | X30: =AVERAGEIFS(E30:T30,E30:T30,">"&V30, E30:T30, "<"&W30) -> 44 | Y30: =X30*0.9 -> 39.6 | Z30: =X30*1.1 -> 48.4 | AB30: 6 | AC30: =D30 -> ES-25 (fundo da laje-PLE03) | AD30: -90 | AE30: =X30 -> 44 | AF30: =$AS$20 -> 0.97919217 | AG30: =AE30*AF30 -> 43.084455 | AH30: =SUMPRODUCT(INDEX(Curvas!$B$3:$E$5,MATCH(AD30,Curvas!$A$3:$A$5,0),0),CHOOSE({1,2,3,4},AG30^3,AG30^2,AG30,1)) -> 33.16124 | AI30: {=SUMPRODUCT(TRANSPOSE($AM$6:$AM$12),CHOOSE({1,2,3,4,5,6,7},AH30^6,AH30^5,AH30^4,AH30^3,AH30^2,AH30,1))} -> 0.60299412 | AJ30: =AH30*AI30 -> 19.996033 | AK30: =$AK$2*5600*SQRT($AJ30)/1000 -> 25.041477
D31: ES-26 (fundo da laje-PLE01) | E31: 40 | F31: 41 | G31: 43 | H31: 43 | I31: 43 | J31: 44 | K31: 44 | L31: 45 | M31: 48 | N31: 48 | O31: 48 | P31: 48 | Q31: 49 | R31: 49 | S31: 50 | T31: 59 | U31: =AVERAGE(E31:T31) -> 46.375 | V31: =U31*0.9 -> 41.7375 | W31: =U31*1.1 -> 51.0125 | X31: =AVERAGEIFS(E31:T31,E31:T31,">"&V31, E31:T31, "<"&W31) -> 46.307692 | Y31: =X31*0.9 -> 41.676923 | Z31: =X31*1.1 -> 50.938462 | AB31: 6 | AC31: =D31 -> ES-26 (fundo da laje-PLE01) | AD31: -90 | AE31: =X31 -> 46.307692 | AF31: =$AS$20 -> 0.97919217 | AG31: =AE31*AF31 -> 45.34413 | AH31: =SUMPRODUCT(INDEX(Curvas!$B$3:$E$5,MATCH(AD31,Curvas!$A$3:$A$5,0),0),CHOOSE({1,2,3,4},AG31^3,AG31^2,AG31,1)) -> 36.528286 | AI31: {=SUMPRODUCT(TRANSPOSE($AM$6:$AM$12),CHOOSE({1,2,3,4,5,6,7},AH31^6,AH31^5,AH31^4,AH31^3,AH31^2,AH31,1))} -> 0.60035927 | AJ31: =AH31*AI31 -> 21.930095 | AK31: =$AK$2*5600*SQRT($AJ31)/1000 -> 26.224564
D32: ES-27 (bloco de fundação-CP09) | E32: 39 | F32: 39 | G32: 41 | H32: 41 | I32: 43 | J32: 43 | K32: 43 | L32: 43 | M32: 43 | N32: 43 | O32: 44 | P32: 44 | Q32: 44 | R32: 44 | S32: 45 | T32: 45 | U32: =AVERAGE(E32:T32) -> 42.75 | V32: =U32*0.9 -> 38.475 | W32: =U32*1.1 -> 47.025 | X32: =AVERAGEIFS(E32:T32,E32:T32,">"&V32, E32:T32, "<"&W32) -> 42.75 | Y32: =X32*0.9 -> 38.475 | Z32: =X32*1.1 -> 47.025 | AB32: 6 | AC32: =D32 -> ES-27 (bloco de fundação-CP09) | AD32: 0 | AE32: =X32 -> 42.75 | AF32: =$AS$20 -> 0.97919217 | AG32: =AE32*AF32 -> 41.860465 | AH32: =SUMPRODUCT(INDEX(Curvas!$B$3:$E$5,MATCH(AD32,Curvas!$A$3:$A$5,0),0),CHOOSE({1,2,3,4},AG32^3,AG32^2,AG32,1)) -> 37.68141 | AI32: {=SUMPRODUCT(TRANSPOSE($AM$6:$AM$12),CHOOSE({1,2,3,4,5,6,7},AH32^6,AH32^5,AH32^4,AH32^3,AH32^2,AH32,1))} -> 0.59995016 | AJ32: =AH32*AI32 -> 22.606968 | AK32: =$AK$2*5600*SQRT($AJ32)/1000 -> 26.6262
AC33: média | AE33: =AVERAGE(AE6:AE32) -> 36.246457 | AG33: =AVERAGE(AG6:AG32) -> 35.516297 | AH33: =AVERAGE(AH6:AH32) -> 27.717317 | AJ33: =AVERAGE(AJ6:AJ32) -> 17.105351 | AK33: =AVERAGE(AK6:AK32) -> 23.077526
F34: Limite inferior da 1ª avaliação | AC34: mediana | AE34: =MEDIAN(AE6:AE32) -> 34.285714 | AG34: =MEDIAN(AG6:AG32) -> 33.572303 | AH34: =MEDIAN(AH6:AH32) -> 25.803762 | AJ34: =MEDIAN(AJ6:AJ32) -> 16.026815 | AK34: =MEDIAN(AK6:AK32) -> 22.418762
F35: Limite superior da 1ª avaliação | AC35: desvio padrão da amostra | AE35: =_xlfn.STDEV.S(AE6:AE32) -> 5.0648398 | AG35: =_xlfn.STDEV.S(AG6:AG32) -> 4.9487204 | AH35: =_xlfn.STDEV.S(AH6:AH32) -> 5.5678584 | AJ35: =_xlfn.STDEV.S(AJ6:AJ32) -> 3.0241395 | AK35: =_xlfn.STDEV.S(AK6:AK32) -> 1.9999412
F36: Limite inferior da 2ª avaliação | AC36: coeficiente de variação | AE36: =AE35/AE33 -> 0.13973338 | AG36: =AG35/AG33 -> 0.13933661 | AH36: =AH35/AH33 -> 0.20088013 | AJ36: =AJ35/AJ33 -> 0.17679494 | AK36: =AK35/AK33 -> 0.086661856
F37: Limite superior da 2ª avaliação | AC37: quantil de 5% da amostra (considerando distribuição normal) | AE37: =AE33-1.645*AE35 -> 27.914796 | AG37: =AG33-1.645*AG35 -> 27.375652 | AH37: =AH33-1.645*AH35 -> 18.55819 | AJ37: =AJ33-1.645*AJ35 -> 12.130642 | AK37: =AK33-1.645*AK35 -> 19.787622
AC39: limite inferior faixa | AE39: limite superior faixa | AG39: redução em R | AJ39: =5/27 -> 0.18518519
AC40: 23 | AE40: 28 | AG40: 0.67
AC41: 28 | AE41: 34 | AG41: 0.63
AC42: 34 | AE42: 50 | AG42: 0.6
...

Sheet Curvas
B1: coeficientes do polinômio do 3grau y= A*(x^3)+B*(x^2)+C*x+D | G1: direcao | H1: -90
A2: direção do impacto | B2: A | C2: B | D2: C | E2: D
A3: 90 | B3: 0.0002308 | C3: -0.01530244 | D3: 1.5999095 | E3: -15.527607 | H3: {=INDEX(B3:E5,MATCH($H$1,A3:A5,0),0)} -> 0.00027478 | I3: -0.0251159 | J3: 2.0991653 | K3: -32.634169
A4: 0 | B4: 0.00012208 | C4: -0.00651333 | D4: 1.4013221 | E4: -18.520102 | H4: {=CHOOSE({1,2,3,4},C10^3,C10^2,C10,1)} -> 1157.9558 | I4: 110.271 | J4: 10.501 | K4: 1
A5: -90 | B5: 0.00027478 | C5: -0.0251159 | D5: 2.0991653 | E5: -32.634169 | H5: =SUMPRODUCT(INDEX(B3:E5,MATCH($H$1,A3:A5,0),0),CHOOSE({1,2,3,4},C10^3,C10^2,C10,1)) -> -13.042206
H7: =IFERROR(VLOOKUP($H$1,A3:E5,2,FALSE),"nao encontrado") -> 0.00027478
H8: =VLOOKUP(H1,A4:E6,2,FALSE) -> 0.00027478
B9: R | C9: fck (0 graus) | E9: func cubica | F9: erro
B10: 22.002862 | C10: 10.501 | E10: =$B$4*B10^3+$C$4*B10^2+$D$4*B10+$E$4 -> 10.460138 | F10: =C10-E10 -> 0.040861902
B11: 23.004297 | C11: 11.803603 | E11: =$B$4*B11^3+$C$4*B11^2+$D$4*B11+$E$4 -> 11.755669 | F11: =C11-E11 -> 0.047933472
B12: 24.005727 | C12: 13.106211 | E12: =$B$4*B12^3+$C$4*B12^2+$D$4*B12+$E$4 -> 13.055027 | F12: =C12-E12 -> 0.051183712
B13: 25.007156 | C13: 14.308609 | E13: =$B$4*B13^3+$C$4*B13^2+$D$4*B13+$E$4 -> 14.358955 | F13: =C13-E13 -> -0.05034648
B14: 26.008589 | C14: 15.611223 | E14: =$B$4*B14^3+$C$4*B14^2+$D$4*B14+$E$4 -> 15.668193 | F14: =C14-E14 -> -0.056970072
B15: 27.010018 | C15: 16.913831 | E15: =$B$4*B15^3+$C$4*B15^2+$D$4*B15+$E$4 -> 16.983468 | F15: =C15-E15 -> -0.069637006
B16: 27.961374 | C16: 18.216434 | E16: =$B$4*B16^3+$C$4*B16^2+$D$4*B16+$E$4 -> 18.239243 | F16: =C16-E16 -> -0.022808884
B17: 29.01288 | C17: 19.619241 | E17: =$B$4*B17^3+$C$4*B17^2+$D$4*B17+$E$4 -> 19.635089 | F17: =C17-E17 -> -0.015848094
B18: 30.01431 | C18: 20.921843 | E18: =$B$4*B18^3+$C$4*B18^2+$D$4*B18+$E$4 -> 20.972902 | F18: =C18-E18 -> -0.051058581
B19: 31.015739 | C19: 22.324645 | E19: =$B$4*B19^3+$C$4*B19^2+$D$4*B19+$E$4 -> 22.319699 | F19: =C19-E19 -> 0.0049459527
B20: 31.967095 | C20: 23.627253 | E20: =$B$4*B20^3+$C$4*B20^2+$D$4*B20+$E$4 -> 23.608144 | F20: =C20-E20 -> 0.019108802
B21: 33.018601 | C21: 25.03006 | E21: =$B$4*B21^3+$C$4*B21^2+$D$4*B21+$E$4 -> 25.043191 | F21: =C21-E21 -> -0.013130371
... B29: 41.030046 | C29: 36.452904 | E29: =$B$4*B29^3+$C$4*B29^2+$D$4*B29+$E$4 -> 36.443634 | F29: =C29-E29 -> 0.0092695018
B30: 41.981402 | C30: 37.855714 | E30: =$B$4*B30^3+$C$4*B30^2+$D$4*B30+$E$4 -> 37.862676 | F30: =C30-E30 -> -0.0069625711 | G30: 25 | H30: 14 | J30: 26 | K30: 10
B31: 43.032905 | C31: 39.458916 | E31: =$B$4*B31^3+$C$4*B31^2+$D$4*B31+$E$4 -> 39.449787 | F31: =C31-E31 -> 0.0091286658 | G31: 30 | H31: 21 | J31: 30 | K31: 15
B32: 43.984261 | C32: 40.961922 | E32: =$B$4*B32^3+$C$4*B32^2+$D$4*B32+$E$4 -> 40.903335 | F32: =C32-E32 -> 0.058587173 | G32: 35 | H32: 28 | J32: 35 | K32: 22
B33: 45.035764 | C33: 42.565132 | E33: =$B$4*B33^3+$C$4*B33^2+$D$4*B33+$E$4 -> 42.530128 | F33: =C33-E33 -> 0.035004453 | G33: 40 | H33: 35 | J33: 40 | K33: 29
B34: 46.037196 | C34: 44.068138 | E34: =$B$4*B34^3+$C$4*B34^2+$D$4*B34+$E$4 -> 44.099962 | F34: =C34-E34 -> -0.031824035 | G34: 45 | H34: 42 | J34: 45 | K34: 36
B35: 46.988552 | C35: 45.571144 | E35: =$B$4*B35^3+$C$4*B35^2+$D$4*B35+$E$4 -> 45.61051 | F35: =C35-E35 -> -0.039365045 | G35: 50 | H35: 50.5 | J35: 50 | K35: 44
B36: 48.040055 | C36: 47.274551 | E36: =$B$4*B36^3+$C$4*B36^2+$D$4*B36+$E$4 -> 47.30262 | F36: =C36-E36 -> -0.028068725
B37: 49.041488 | C37: 48.877759 | E37: =$B$4*B37^3+$C$4*B37^2+$D$4*B37+$E$4 -> 48.936923 | F37: =C37-E37 -> -0.059164223 | I37: =0.0062*J30*J30 + 0.9433*J30 - 18.738 -> 9.979
B38: 50.042915 | C38: 50.480961 | E38: =$B$4*B38^3+$C$4*B38^2+$D$4*B38+$E$4 -> 50.594178 | F38: =C38-E38 -> -0.11321679 | G38: =0.0054*G30*G30 + 1.0411*G30 - 15.214 -> 14.1885 | I38: =0.0062*J31*J31 + 0.9433*J31 - 18.738 -> 15.141
B39: 51.044347 | C39: 52.284572 | E39: =$B$4*B39^3+$C$4*B39^2+$D$4*B39+$E$4 -> 52.275138 | F39: =C39-E39 -> 0.0094339253 | G39: =0.0054*G31*G31 + 1.0411*G31 - 15.214 -> 20.879 | I39: =0.0062*J32*J32 + 0.9433*J32 - 18.738 -> 21.8725
B40: 52.045779 | C40: 53.987976 | E40: =$B$4*B40^3+$C$4*B40^2+$D$4*B40+$E$4 -> 53.980531 | F40: =C40-E40 -> 0.0074450212 | G40: =0.0054*G32*G32 + 1.0411*G32 - 15.214 -> 27.8395 | I40: =0.0062*J33*J33 + 0.9433*J33 - 18.738 -> 28.914
B41: 53.047212 | C41: 55.691384 | E41: =$B$4*B41^3+$C$4*B41^2+$D$4*B41+$E$4 -> 55.711091 | F41: =C41-E41 -> -0.019707361 | G41: =0.0054*G33*G33 + 1.0411*G33 - 15.214 -> 35.07 | I41: =0.0062*J34*J34 + 0.9433*J34 - 18.738 -> 36.2655
B42: 53.998568 | C42: 57.494989 | E42: =$B$4*B42^3+$C$4*B42^2+$D$4*B42+$E$4 -> 57.379097 | F42: =C42-E42 -> 0.11589264 | G42: =0.0054*G34*G34 + 1.0411*G34 - 15.214 -> 42.5705 | I42: =0.0062*J35*J35 + 0.9433*J35 - 18.738 -> 43.927
B45: R | C45: fck (-90 graus) | E45: func cubica | F45: erro
B46: 27.010014 | C46: 11.257205 | E46: =$B$5*B46^3+$C$5*B46^2+$D$5*B46+$E$5 -> 11.155755 | F46: =C46-E46 -> 0.10145011
B47: 27.971386 | C47: 12.459609 | E47: =$B$5*B47^3+$C$5*B47^2+$D$5*B47+$E$5 -> 12.445251 | F47: =C47-E47 -> 0.014358398
B48: 28.992846 | C48: 13.782245 | E48: =$B$5*B48^3+$C$5*B48^2+$D$5*B48+$E$5 -> 13.811207 | F48: =C48-E48 -> -0.0289622
B49: 30.014305 | C49: 15.104897 | E49: =$B$5*B49^3+$C$5*B49^2+$D$5*B49+$E$5 -> 15.174625 | F49: =C49-E49 -> -0.069728229
B50: 31.035771 | C50: 16.547782 | E50: =$B$5*B50^3+$C$5*B50^2+$D$5*B50+$E$5 -> 16.537272 | F50: =C50-E50 -> 0.010510128
...

Sheet compPauloBArroso
AI2: aE | AJ2: 1
AH3: y = -1.343249E-10x6 + 3.420646E-08x5 - 3.490515E-06x4 + 1.792832E-04x3 - 4.704508E-03x2 + 5.401466E-02x + 4.752819E-01 | AO3: {=CHOOSE({1,2,3,4},AG6^3,AG6^2,AG6,1)} -> 19574.973 | AP3: 726.33021 | AQ3: 26.950514 | AR3: 1
D4: Área de Ensaio | E4: Índices Esclerométricos | U4: 1ª avaliação | X4: 2ª avaliação | AB4: Produndidade de carbonatação (mm) | AC4: =D4 -> Área de Ensaio | AD4: Direção/ Sentido do Golpe (graus) | AE4: Índice escleromé-trico R | AF4: Correção em R devido à calibração (coef. k) | AG4: Resistência à compressão (descons. carbonatação) fck(MPa) | AH4: Redução em fck devido a carbona-tação | AI4: Resist à compr. corrigida fck(MPa) | AJ4: Módulo de elasticdade (Gpa) NBR6118 | AO4: =$AG$6^3 -> 19574.973 | AP4: =$AG$6^2 -> 726.33021 | AQ4: =$AG$6^1 -> 26.950514 | AR4: 1
E5: 1 | F5: 2 | G5: 3 | H5: 4 | I5: 5 | J5: 6 | K5: 7 | L5: 8 | M5: 9 | N5: 10 | O5: 11 | P5: 12 | Q5: 13 | R5: 14 | S5: 15 | T5: 16 | U5: Média inicial | V5: Limite inferior (0,9*média) | W5: Limite superior (1,1*média) | X5: Média Final | Y5: Limite inferior (0,9*média) | Z5: Limite superior (1,1*média) | AL5: coeficientes | AP5: Impacto | AQ5: Índice esclerométrico de cada impacto
D6: ES-01 (túnel de descarga-PT05) | E6: 30 | F6: 32 | G6: 32 | H6: 33 | I6: 34 | J6: 34 | K6: 35 | L6: 36 | M6: 36 | N6: 36 | O6: 36 | P6: 36 | Q6: 36 | R6: 37 | S6: 37 | T6: 37 | U6: =AVERAGE(E6:T6) -> 34.8125 | V6: =U6*0.9 -> 31.33125 | W6: =U6*1.1 -> 38.29375 | X6: =AVERAGEIFS(E6:T6,E6:T6,">"&V6, E6:T6, "<"&W6) -> 35.133333 | Y6: =X6*0.9 -> 31.62 | Z6: =X6*1.1 -> 38.646667 | AB6: 49 | AC6: =D6 -> ES-01 (túnel de descarga-PT05) | AD6: 0 | AE6: =X6 -> 35.133333 | AF6: =AE6*$AQ$20 -> 34.402285 | AG6: =SUMPRODUCT(INDEX(Curvas!$B$3:$E$5,MATCH(AD6,Curvas!$A$3:$A$5,0),0),CHOOSE({1,2,3,4},AF6^3,AF6^2,AF6,1)) -> 26.950514 | AH6: 0.681 | AI6: =AG6*AH6 -> 18.3533 | AJ6: =$AJ$2*5600*SQRT($AI6)/1000 -> 23.990821 | AL6: -1.343249e-10 | AM6: a6 | AO6: =SUMPRODUCT(INDEX(Curvas!$B$3:$E$5,MATCH(AD6,Curvas!$A$3:$A$5,0),0),CHOOSE({1,2,3,4},AF6^3,AF6^2,AF6,1)) -> 26.950514 | AP6: 1 | AQ6: 81
D7: ES-02 (túnel de descarga-PT03) | E7: 30 | F7: 30 | G7: 30 | H7: 30 | I7: 30 | J7: 30 | K7: 31 | L7: 31 | M7: 31 | N7: 31 | O7: 32 | P7: 32 | Q7: 32 | R7: 32 | S7: 32 | T7: 32 | U7: =AVERAGE(E7:T7) -> 31 | V7: =U7*0.9 -> 27.9 | W7: =U7*1.1 -> 34.1 | X7: =AVERAGEIFS(E7:T7,E7:T7,">"&V7, E7:T7, "<"&W7) -> 31 | Y7: =X7*0.9 -> 27.9 | Z7: =X7*1.1 -> 34.1 | AB7: 59.3 | AC7: =D7 -> ES-02 (túnel de descarga-PT03) | AD7: 0 | AE7: =X7 -> 31 | AF7: =AE7*$AQ$20 -> 30.354957 | AG7: =SUMPRODUCT(INDEX(Curvas!$B$3:$E$5,MATCH(AD7,Curvas!$A$3:$A$5,0),0),CHOOSE({1,2,3,4},AF7^3,AF7^2,AF7,1)) -> 21.429985 | AH7: 0.681 | AI7: =AG7*AH7 -> 14.59382 | AJ7: =$AJ$2*5600*SQRT($AI7)/1000 -> 21.393041 | AL7: 3.420646e-08 | AM7: a5 | AO7: =SUMPRODUCT(INDEX(Curvas!$B$3:$E$5,MATCH(AD7,Curvas!$A$3:$A$5,0),0),CHOOSE({1,2,3,4},AF7^3,AF7^2,AF7,1)) -> 21.429985 | AP7: 2 | AQ7: 81
D8: ES-03 (túnel de descarga-PT06) | E8: 27 | F8: 30 | G8: 31 | H8: 31 | I8: 31 | J8: 31 | K8: 32 | L8: 32 | M8: 32 | N8: 33 | O8: 33 | P8: 34 | Q8: 34 | R8: 37 | S8: 39 | T8: 39 | U8: =AVERAGE(E8:T8) -> 32.875 | V8: =U8*0.9 -> 29.5875 | W8: =U8*1.1 -> 36.1625 | X8: =AVERAGEIFS(E8:T8,E8:T8,">"&V8, E8:T8, "<"&W8) -> 32 | Y8: =X8*0.9 -> 28.8 | Z8: =X8*1.1 -> 35.2 | AB8: 64.3 | AC8: =D8 -> ES-03 (túnel de descarga-PT06) | AD8: 0 | AE8: =X8 -> 32 | AF8: =AE8*$AQ$20 -> 31.334149 | AG8: =SUMPRODUCT(INDEX(Curvas!$B$3:$E$5,MATCH(AD8,Curvas!$A$3:$A$5,0),0),CHOOSE({1,2,3,4},AF8^3,AF8^2,AF8,1)) -> 22.749922 | AH8: 0.681 | AI8: =AG8*AH8 -> 15.492697 | AJ8: =$AJ$2*5600*SQRT($AI8)/1000 -> 22.042027 | AL8: -3.490515e-06 | AM8: a4 | AO8: =SUMPRODUCT(INDEX(Curvas!$B$3:$E$5,MATCH(AD8,Curvas!$A$3:$A$5,0),0),CHOOSE({1,2,3,4},AF8^3,AF8^2,AF8,1)) -> 22.749922 | AP8: 3 | AQ8: 81
D9: ES-04 (estaca 71-N) | E9: 33 | F9: 33 | G9: 34 | H9: 34 | I9: 36 | J9: 36 | K9: 37 | L9: 37 | M9: 37 | N9: 37 | O9: 38 | P9: 38 | Q9: 39 | R9: 39 | S9: 40 | T9: 48 | U9: =AVERAGE(E9:T9) -> 37.25 | V9: =U9*0.9 -> 33.525 | W9: =U9*1.1 -> 40.975 | X9: =AVERAGEIFS(E9:T9,E9:T9,">"&V9, E9:T9, "<"&W9) -> 37.076923 | Y9: =X9*0.9 -> 33.369231 | Z9: =X9*1.1 -> 40.784615 | AB9: 49.5 | AC9: =D9 -> ES-04 (estaca 71-N) | AD9: 0 | AE9: =X9 -> 37.076923 | AF9: =AE9*$AQ$20 -> 36.305433 | AG9: =SUMPRODUCT(INDEX(Curvas!$B$3:$E$5,MATCH(AD9,Curvas!$A$3:$A$5,0),0),CHOOSE({1,2,3,4},AF9^3,AF9^2,AF9,1)) -> 29.612355 | AH9: 0.681 | AI9: =AG9*AH9 -> 20.166014 | AJ9: =$AJ$2*5600*SQRT($AI9)/1000 -> 25.147688 | AL9: 0.0001792832 | AM9: a3 | AO9: =SUMPRODUCT(INDEX(Curvas!$B$3:$E$5,MATCH(AD9,Curvas!$A$3:$A$5,0),0),CHOOSE({1,2,3,4},AF9^3,AF9^2,AF9,1)) -> 29.612355 | AP9: 4 | AQ9: 82
D10: ES-05 (estaca 71-O) | E10: 31 | F10: 34 | G10: 34 | H10: 35 | I10: 35 | J10: 36 | K10: 36 | L10: 36 | M10: 36 | N10: 38 | O10: 38 | P10: 38 | Q10: 38 | R10: 39 | S10: 44 | T10: 48 | U10: =AVERAGE(E10:T10) -> 37.25 | V10: =U10*0.9 -> 33.525 | W10: =U10*1.1 -> 40.975 | X10: =AVERAGEIFS(E10:T10,E10:T10,">"&V10, E10:T10, "<"&W10) -> 36.384615 | Y10: =X10*0.9 -> 32.746154 | Z10: =X10*1.1 -> 40.023077 | AB10: 50.5 | AC10: =D10 -> ES-05 (estaca 71-O) | AD10: 0 | AE10: =X10 -> 36.384615 | AF10: =AE10*$AQ$20 -> 35.62753 | AG10: =SUMPRODUCT(INDEX(Curvas!$B$3:$E$5,MATCH(AD10,Curvas!$A$3:$A$5,0),0),CHOOSE({1,2,3,4},AF10^3,AF10^2,AF10,1)) -> 28.658833 | AH10: 0.681 | AI10: =AG10*AH10 -> 19.516666 | AJ10: =$AJ$2*5600*SQRT($AI10)/1000 -> 24.739495 | AL10: -0.004704508 | AM10: a2 | AO10: =SUMPRODUCT(INDEX(Curvas!$B$3:$E$5,MATCH(AD10,Curvas!$A$3:$A$5,0),0),CHOOSE({1,2,3,4},AF10^3,AF10^2,AF10,1)) -> 28.658833 | AP10: 5 | AQ10: 82
D11: ES-06 (estaca 71-S) | E11: 35 | F11: 35 | G11: 36 | H11: 36 | I11: 37 | J11: 38 | K11: 38 | L11: 38 | M11: 41 | N11: 41 | O11: 42 | P11: 42 | Q11: 44 | R11: 45 | S11: 53 | T11: 58 | U11: =AVERAGE(E11:T11) -> 41.1875 | V11: =U11*0.9 -> 37.06875 | W11: =U11*1.1 -> 45.30625 | X11: =AVERAGEIFS(E11:T11,E11:T11,">"&V11, E11:T11, "<"&W11) -> 41 | Y11: =X11*0.9 -> 36.9 | Z11: =X11*1.1 -> 45.1 | AB11: 55 | AC11: =D11 -> ES-06 (estaca 71-S) | AD11: 0 | AE11: =X11 -> 41 | AF11: =AE11*$AQ$20 -> 40.146879 | AG11: =SUMPRODUCT(INDEX(Curvas!$B$3:$E$5,MATCH(AD11,Curvas!$A$3:$A$5,0),0),CHOOSE({1,2,3,4},AF11^3,AF11^2,AF11,1)) -> 35.14011 | AH11: 0.681 | AI11: =AG11*AH11 -> 23.930415 | AJ11: =$AJ$2*5600*SQRT($AI11)/1000 -> 27.394485 | AL11: 0.05401466 | AM11: a1 | AO11: =SUMPRODUCT(INDEX(Curvas!$B$3:$E$5,MATCH(AD11,Curvas!$A$3:$A$5,0),0),CHOOSE({1,2,3,4},AF11^3,AF11^2,AF11,1)) -> 35.14011 | AP11: 6 | AQ11: 82
D12: ES-07 (estaca 71-L) | E12: 31 | F12: 35 | G12: 36 | H12: 36 | I12: 37 | J12: 37 | K12: 38 | L12: 38 | M12: 38 | N12: 39 | O12: 39 | P12: 40 | Q12: 41 | R12: 41 | S12: 45 | T12: 46 | U12: =AVERAGE(E12:T12) -> 38.5625 | V12: =U12*0.9 -> 34.70625 | W12: =U12*1.1 -> 42.41875 | X12: =AVERAGEIFS(E12:T12,E12:T12,">"&V12, E12:T12, "<"&W12) -> 38.076923 | Y12: =X12*0.9 -> 34.269231 | Z12: =X12*1.1 -> 41.884615 | AB12: 57 | AC12: =D12 -> ES-07 (estaca 71-L) | AD12: 0 | AE12: =X12 -> 38.076923 | AF12: =AE12*$AQ$20 -> 37.284625 | AG12: =SUMPRODUCT(INDEX(Curvas!$B$3:$E$5,MATCH(AD12,Curvas!$A$3:$A$5,0),0),CHOOSE({1,2,3,4},AF12^3,AF12^2,AF12,1)) -> 31.00073 | AH12: 0.681 | AI12: =AG12*AH12 -> 21.111497 | AJ12: =$AJ$2*5600*SQRT($AI12)/1000 -> 25.73046 | AL12: 0.4752819 | AM12: a0 | AO12: =SUMPRODUCT(INDEX(Curvas!$B$3:$E$5,MATCH(AD12,Curvas!$A$3:$A$5,0),0),CHOOSE({1,2,3,4},AF12^3,AF12^2,AF12,1)) -> 31.00073 | AP12: 7 | AQ12: 82
D13: ES-08 (estaca 60-N) | E13: 26 | F13: 27 | G13: 28 | H13: 29 | I13: 30 | J13: 30 | K13: 32 | L13: 32 | M13: 32 | N13: 33 | O13: 33 | P13: 34 | Q13: 35 | R13: 36 | S13: 36 | T13: 37 | U13: =AVERAGE(E13:T13) -> 31.875 | V13: =U13*0.9 -> 28.6875 | W13: =U13*1.1 -> 35.0625 | X13: =AVERAGEIFS(E13:T13,E13:T13,">"&V13, E13:T13, "<"&W13) -> 32 | Y13: =X13*0.9 -> 28.8 | Z13: =X13*1.1 -> 35.2 | AB13: 70 | AC13: =D13 -> ES-08 (estaca 60-N) | AD13: 0 | AE13: =X13 -> 32 | AF13: =AE13*$AQ$20 -> 31.334149 | AG13: =SUMPRODUCT(INDEX(Curvas!$B$3:$E$5,MATCH(AD13,Curvas!$A$3:$A$5,0),0),CHOOSE({1,2,3,4},AF13^3,AF13^2,AF13,1)) -> 22.749922 | AH13: 0.681 | AI13: =AG13*AH13 -> 15.492697 | AJ13: =$AJ$2*5600*SQRT($AI13)/1000 -> 22.042027 | AO13: =SUMPRODUCT(INDEX(Curvas!$B$3:$E$5,MATCH(AD13,Curvas!$A$3:$A$5,0),0),CHOOSE({1,2,3,4},AF13^3,AF13^2,AF13,1)) -> 22.749922 | AP13: 8 | AQ13: 82
D14: ES-09 (estaca 60-O) | E14: 29 | F14: 30 | G14: 30 | H14: 30 | I14: 30 | J14: 31 | K14: 31 | L14: 32 | M14: 32 | N14: 32 | O14: 33 | P14: 34 | Q14: 35 | R14: 35 | S14: 36 | T14: 36 | U14: =AVERAGE(E14:T14) -> 32.25 | V14: =U14*0.9 -> 29.025 | W14: =U14*1.1 -> 35.475 | X14: =AVERAGEIFS(E14:T14,E14:T14,">"&V14, E14:T14, "<"&W14) -> 31.923077 | Y14: =X14*0.9 -> 28.730769 | Z14: =X14*1.1 -> 35.115385 | AB14: 62 | AC14: =D14 -> ES-09 (estaca 60-O) | AD14: 0 | AE14: =X14 -> 31.923077 | AF14: =AE14*$AQ$20 -> 31.258827 | AG14: =SUMPRODUCT(INDEX(Curvas!$B$3:$E$5,MATCH(AD14,Curvas!$A$3:$A$5,0),0),CHOOSE({1,2,3,4},AF14^3,AF14^2,AF14,1)) -> 22.648059 | AH14: 0.681 | AI14: =AG14*AH14 -> 15.423328 | AJ14: =$AJ$2*5600*SQRT($AI14)/1000 -> 21.992626 | AO14: =SUMPRODUCT(INDEX(Curvas!$B$3:$E$5,MATCH(AD14,Curvas!$A$3:$A$5,0),0),CHOOSE({1,2,3,4},AF14^3,AF14^2,AF14,1)) -> 22.648059 | AP14: 9 | AQ14: 82
D15: ES-10 (estaca 60-S) | E15: 30 | F15: 30 | G15: 31 | H15: 32 | I15: 32 | J15: 32 | K15: 33 | L15: 33 | M15: 33 | N15: 34 | O15: 34 | P15: 35 | Q15: 35 | R15: 35 | S15: 37 | T15: 38 | U15: =AVERAGE(E15:T15) -> 33.375 | V15: =U15*0.9 -> 30.0375 | W15: =U15*1.1 -> 36.7125 | X15: =AVERAGEIFS(E15:T15,E15:T15,">"&V15, E15:T15, "<"&W15) -> 33.25 | Y15: =X15*0.9 -> 29.925 | Z15: =X15*1.1 -> 36.575 | AB15: 6 | AC15: =D15 -> ES-10 (estaca 60-S) | AD15: 0 | AE15: =X15 -> 33.25 | AF15: =AE15*$AQ$20 -> 32.55814 | AG15: =SUMPRODUCT(INDEX(Curvas!$B$3:$E$5,MATCH(AD15,Curvas!$A$3:$A$5,0),0),CHOOSE({1,2,3,4},AF15^3,AF15^2,AF15,1)) -> 24.413306 | AH15: 0.681 | AI15: =AG15*AH15 -> 16.625461 | AJ15: =$AJ$2*5600*SQRT($AI15)/1000 -> 22.833626 | AO15: =SUMPRODUCT(INDEX(Curvas!$B$3:$E$5,MATCH(AD15,Curvas!$A$3:$A$5,0),0),CHOOSE({1,2,3,4},AF15^3,AF15^2,AF15,1)) -> 24.413306 | AP15: 10 | AQ15: 82
D16: ES-11 (estaca 60-L) | E16: 30 | F16: 30 | G16: 31 | H16: 32 | I16: 32 | J16: 32 | K16: 33 | L16: 33 | M16: 33 | N16: 33 | O16: 34 | P16: 34 | Q16: 34 | R16: 34 | S16: 37 | T16: 39 | U16: =AVERAGE(E16:T16) -> 33.1875 | V16: =U16*0.9 -> 29.86875 | W16: =U16*1.1 -> 36.50625 | X16: =AVERAGEIFS(E16:T16,E16:T16,">"&V16, E16:T16, "<"&W16) -> 32.5 | Y16: =X16*0.9 -> 29.25 | Z16: =X16*1.1 -> 35.75 | AB16: 6 | AC16: =D16 -> ES-11 (estaca 60-L) | AD16: 0 | AE16: =X16 -> 32.5 | AF16: =AE16*$AQ$20 -> 31.823745 | AG16: =SUMPRODUCT(INDEX(Curvas!$B$3:$E$5,MATCH(AD16,Curvas!$A$3:$A$5,0),0),CHOOSE({1,2,3,4},AF16^3,AF16^2,AF16,1)) -> 23.413416 | AH16: 0.681 | AI16: =AG16*AH16 -> 15.944536 | AJ16: =$AJ$2*5600*SQRT($AI16)/1000 -> 22.361142 | AO16: =SUMPRODUCT(INDEX(Curvas!$B$3:$E$5,MATCH(AD16,Curvas!$A$3:$A$5,0),0),CHOOSE({1,2,3,4},AF16^3,AF16^2,AF16,1)) -> 23.413416 | AP16: somatório | AQ16: =SUM(AQ6:AQ15) -> 817
D17: ES-12 (estaca 44-N) | E17: 28 | F17: 30 | G17: 30 | H17: 30 | I17: 30 | J17: 32 | K17: 32 | L17: 32 | M17: 32 | N17: 32 | O17: 32 | P17: 33 | Q17: 33 | R17: 37 | S17: 39 | T17: 40 | U17: =AVERAGE(E17:T17) -> 32.625 | V17: =U17*0.9 -> 29.3625 | W17: =U17*1.1 -> 35.8875 | X17: =AVERAGEIFS(E17:T17,E17:T17,">"&V17, E17:T17, "<"&W17) -> 31.5 | Y17: =X17*0.9 -> 28.35 | Z17: =X17*1.1 -> 34.65 | AB17: 64.8 | AC17: =D17 -> ES-12 (estaca 44-N) | AD17: 0 | AE17: =X17 -> 31.5 | AF17: =AE17*$AQ$20 -> 30.844553 | AG17: =SUMPRODUCT(INDEX(Curvas!$B$3:$E$5,MATCH(AD17,Curvas!$A$3:$A$5,0),0),CHOOSE({1,2,3,4},AF17^3,AF17^2,AF17,1)) -> 22.088807 | AH17: 0.681 | AI17: =AG17*AH17 -> 15.042478 | AJ17: =$AJ$2*5600*SQRT($AI17)/1000 -> 21.719394 | AO17: =SUMPRODUCT(INDEX(Curvas!$B$3:$E$5,MATCH(AD17,Curvas!$A$3:$A$5,0),0),CHOOSE({1,2,3,4},AF17^3,AF17^2,AF17,1)) -> 22.088807 | AP17: número de impactos | AQ17: =COUNT(AQ6:AQ15) -> 10
D18: ES-13 (estaca 44-O) | E18: 25 | F18: 29 | G18: 30 | H18: 32 | I18: 32 | J18: 32 | K18: 32 | L18: 32 | M18: 32 | N18: 32 | O18: 32 | P18: 33 | Q18: 34 | R18: 34 | S18: 35 | T18: 38 | U18: =AVERAGE(E18:T18) -> 32.125 | V18: =U18*0.9 -> 28.9125 | W18: =U18*1.1 -> 35.3375 | X18: =AVERAGEIFS(E18:T18,E18:T18,">"&V18, E18:T18, "<"&W18) -> 32.214286 | Y18: =X18*0.9 -> 28.992857 | Z18: =X18*1.1 -> 35.435714 | AB18: 6 | AC18: =D18 -> ES-13 (estaca 44-O) | AD18: 0 | AE18: =X18 -> 32.214286 | AF18: =AE18*$AQ$20 -> 31.543976 | AG18: =SUMPRODUCT(INDEX(Curvas!$B$3:$E$5,MATCH(AD18,Curvas!$A$3:$A$5,0),0),CHOOSE({1,2,3,4},AF18^3,AF18^2,AF18,1)) -> 23.03398 | AH18: 0.681 | AI18: =AG18*AH18 -> 15.686141 | AJ18: =$AJ$2*5600*SQRT($AI18)/1000 -> 22.17921 | AO18: =SUMPRODUCT(INDEX(Curvas!$B$3:$E$5,MATCH(AD18,Curvas!$A$3:$A$5,0),0),CHOOSE({1,2,3,4},AF18^3,AF18^2,AF18,1)) -> 23.03398 | AP18: Índice esclerométrico nominal | AQ18: 80
D19: ES-14 (estaca 44-S) | E19: 29 | F19: 30 | G19: 30 | H19: 30 | I19: 31 | J19: 31 | K19: 32 | L19: 32 | M19: 33 | N19: 33 | O19: 34 | P19: 34 | Q19: 35 | R19: 35 | S19: 38 | T19: 47 | U19: =AVERAGE(E19:T19) -> 33.375 | V19: =U19*0.9 -> 30.0375 | W19: =U19*1.1 -> 36.7125 | X19: =AVERAGEIFS(E19:T19,E19:T19,">"&V19, E19:T19, "<"&W19) -> 33 | Y19: =X19*0.9 -> 29.7 | Z19: =X19*1.1 -> 36.3 | AB19: 6 | AC19: =D19 -> ES-14 (estaca 44-S) | AD19: 0 | AE19: =X19 -> 33 | AF19: =AE19*$AQ$20 -> 32.313341 | AG19: =SUMPRODUCT(INDEX(Curvas!$B$3:$E$5,MATCH(AD19,Curvas!$A$3:$A$5,0),0),CHOOSE({1,2,3,4},AF19^3,AF19^2,AF19,1)) -> 24.079375 | AH19: 0.681 | AI19: =AG19*AH19 -> 16.398054 | AJ19: =$AJ$2*5600*SQRT($AI19)/1000 -> 22.676926 | AO19: =SUMPRODUCT(INDEX(Curvas!$B$3:$E$5,MATCH(AD19,Curvas!$A$3:$A$5,0),0),CHOOSE({1,2,3,4},AF19^3,AF19^2,AF19,1)) -> 24.079375
D20: ES-15 (estaca 44-L) | E20: 26 | F20: 29 | G20: 29 | H20: 29 | I20: 29 | J20: 29 | K20: 30 | L20: 30 | M20: 30 | N20: 30 | O20: 30 | P20: 31 | Q20: 32 | R20: 33 | S20: 34 | T20: 36 | U20: =AVERAGE(E20:T20) -> 30.4375 | V20: =U20*0.9 -> 27.39375 | W20: =U20*1.1 -> 33.48125 | X20: =AVERAGEIFS(E20:T20,E20:T20,">"&V20, E20:T20, "<"&W20) -> 30.076923 | Y20: =X20*0.9 -> 27.069231 | Z20: =X20*1.1 -> 33.084615 | AB20: 6 | AC20: =D20 -> ES-15 (estaca 44-L) | AD20: 0 | AE20: =X20 -> 30.076923 | AF20: =AE20*$AQ$20 -> 29.451087 | AG20: =SUMPRODUCT(INDEX(Curvas!$B$3:$E$5,MATCH(AD20,Curvas!$A$3:$A$5,0),0),CHOOSE({1,2,3,4},AF20^3,AF20^2,AF20,1)) -> 20.219433 | AH20: 0.681 | AI20: =AG20*AH20 -> 13.769434 | AJ20: =$AJ$2*5600*SQRT($AI20)/1000 -> 20.780025 | AO20: =SUMPRODUCT(INDEX(Curvas!$B$3:$E$5,MATCH(AD20,Curvas!$A$3:$A$5,0),0),CHOOSE({1,2,3,4},AF20^3,AF20^2,AF20,1)) -> 20.219433 | AP20: coeficiente de correção k | AQ20: =AQ17*AQ18/AQ16 -> 0.97919217
D21: ES-16b (estaca 24-N) | E21: 20 | F21: 30 | G21: 31 | H21: 31 | I21: 31 | J21: 32 | K21: 32 | L21: 32 | M21: 32 | N21: 32 | O21: 32 | P21: 32 | Q21: 34 | R21: 34 | S21: 36 | T21: 38 | U21: =AVERAGE(E21:T21) -> 31.8125 | V21: =U21*0.9 -> 28.63125 | W21: =U21*1.1 -> 34.99375 | X21: =AVERAGEIFS(E21:T21,E21:T21,">"&V21, E21:T21, "<"&W21) -> 31.923077 | Y21: =X21*0.9 -> 28.730769 | Z21: =X21*1.1 -> 35.115385 | AB21: 65.8 | AC21: =D21 -> ES-16b (estaca 24-N) | AD21: 0 | AE21: =X21 -> 31.923077 | AF21: =AE21*$AQ$20 -> 31.258827 | AG21: =SUMPRODUCT(INDEX(Curvas!$B$3:$E$5,MATCH(AD21,Curvas!$A$3:$A$5,0),0),CHOOSE({1,2,3,4},AF21^3,AF21^2,AF21,1)) -> 22.648059 | AH21: 0.681 | AI21: =AG21*AH21 -> 15.423328 | AJ21: =$AJ$2*5600*SQRT($AI21)/1000 -> 21.992626 | AO21: =SUMPRODUCT(INDEX(Curvas!$B$3:$E$5,MATCH(AD21,Curvas!$A$3:$A$5,0),0),CHOOSE({1,2,3,4},AF21^3,AF21^2,AF21,1)) -> 22.648059
D22: ES-17b (estaca 24-S) | E22: 32 | F22: 32 | G22: 33 | H22: 33 | I22: 33 | J22: 34 | K22: 34 | L22: 34 | M22: 34 | N22: 34 | O22: 35 | P22: 35 | Q22: 36 | R22: 36 | S22: 40 | T22: 42 | U22: =AVERAGE(E22:T22) -> 34.8125 | V22: =U22*0.9 -> 31.33125 | W22: =U22*1.1 -> 38.29375 | X22: =AVERAGEIFS(E22:T22,E22:T22,">"&V22, E22:T22, "<"&W22) -> 33.928571 | Y22: =X22*0.9 -> 30.535714 | Z22: =X22*1.1 -> 37.321429 | AB22: 6 | AC22: =D22 -> ES-17b (estaca 24-S) | AD22: 0 | AE22: =X22 -> 33.928571 | AF22: =AE22*$AQ$20 -> 33.222591 | AG22: =SUMPRODUCT(INDEX(Curvas!$B$3:$E$5,MATCH(AD22,Curvas!$A$3:$A$5,0),0),CHOOSE({1,2,3,4},AF22^3,AF22^2,AF22,1)) -> 25.322989 | AH22: 0.681 | AI22: =AG22*AH22 -> 17.244956 | AJ22: =$AJ$2*5600*SQRT($AI22)/1000 -> 23.255146 | AO22: =SUMPRODUCT(INDEX(Curvas!$B$3:$E$5,MATCH(AD22,Curvas!$A$3:$A$5,0),0),CHOOSE({1,2,3,4},AF22^3,AF22^2,AF22,1)) -> 25.322989
D23: ES-18 (estaca 24-L) | E23: 30 | F23: 32 | G23: 32 | H23: 32 | I23: 32 | J23: 33 | K23: 33 | L23: 34 | M23: 34 | N23: 34 | O23: 34 | P23: 36 | Q23: 36 | R23: 37 | S23: 37 | T23: 41 | U23: =AVERAGE(E23:T23) -> 34.1875 | V23: =U23*0.9 -> 30.76875 | W23: =U23*1.1 -> 37.60625 | X23: =AVERAGEIFS(E23:T23,E23:T23,">"&V23, E23:T23, "<"&W23) -> 34 | Y23: =X23*0.9 -> 30.6 | Z23: =X23*1.1 -> 37.4 | AB23: 6 | AC23: =D23 -> ES-18 (estaca 24-L) | AD23: 0 | AE23: =X23 -> 34 | AF23: =AE23*$AQ$20 -> 33.292534 | AG23: =SUMPRODUCT(INDEX(Curvas!$B$3:$E$5,MATCH(AD23,Curvas!$A$3:$A$5,0),0),CHOOSE({1,2,3,4},AF23^3,AF23^2,AF23,1)) -> 25.419032 | AH23: 0.681 | AI23: =AG23*AH23 -> 17.310361 | AJ23: =$AJ$2*5600*SQRT($AI23)/1000 -> 23.299204 | AO23: =SUMPRODUCT(INDEX(Curvas!$B$3:$E$5,MATCH(AD23,Curvas!$A$3:$A$5,0),0),CHOOSE({1,2,3,4},AF23^3,AF23^2,AF23,1)) -> 25.419032
D24: ES-19 (capitel estaca 71-N) | E24: 30 | F24: 31 | G24: 32 | H24: 32 | I24: 33 | J24: 34 | K24: 34 | L24: 34 | M24: 35 | N24: 35 | O24: 36 | P24: 36 | Q24: 36 | R24: 36 | S24: 36 | T24: 40 | U24: =AVERAGE(E24:T24) -> 34.375 | V24: =U24*0.9 -> 30.9375 | W24: =U24*1.1 -> 37.8125 | X24: =AVERAGEIFS(E24:T24,E24:T24,">"&V24, E24:T24, "<"&W24) -> 34.285714 | Y24: =X24*0.9 -> 30.857143 | Z24: =X24*1.1 -> 37.714286 | AB24: 51.3 | AC24: =D24 -> ES-19 (capitel estaca 71-N) | AD24: 0 | AE24: =X24 -> 34.285714 | AF24: =AE24*$AQ$20 -> 33.572303 | AG24: =SUMPRODUCT(INDEX(Curvas!$B$3:$E$5,MATCH(AD24,Curvas!$A$3:$A$5,0),0),CHOOSE({1,2,3,4},AF24^3,AF24^2,AF24,1)) -> 25.803762 | AH24: 0.681 | AI24: =AG24*AH24 -> 17.572362 | AJ24: =$AJ$2*5600*SQRT($AI24)/1000 -> 23.474865 | AO24: =SUMPRODUCT(INDEX(Curvas!$B$3:$E$5,MATCH(AD24,Curvas!$A$3:$A$5,0),0),CHOOSE({1,2,3,4},AF24^3,AF24^2,AF24,1)) -> 25.803762
